Workbook

Sheet Data Worksheet
A1: Client Contact | B1: Client Site | C1: Service Provider | D1: Service Type 1 | E1: Service Type 2 | F1: Service Type 3 | G1: Service Type 4 | H1: Service Type 5 | I1: Connection ID | J1: Contract Term | K1: Contract Start Date | L1: Contract End Date | M1: Billing Gateway
A2: 0 | B2: Not Found | C2: Not Found | D2: Not Found | E2: Not Found | F2: Not Found | G2: Not Found | H2: Not Found | I2: Not Found | J2: Not Found | K2: Not Found | L2: Not Found | M2: Not Found
A3: 0 | B3: Not Found | C3: Not Found | D3: Not Found | E3: Not Found | F3: Not Found | G3: Not Found | H3: Not Found | I3: Not Found | J3: Not Found | K3: Not Found | L3: Not Found | M3: Not Found
A4: 0 | B4: Not Found | C4: Not Found | D4: Not Found | E4: Not Found | F4: Not Found | G4: Not Found | H4: Not Found | I4: Not Found | J4: Not Found | K4: Not Found | L4: Not Found | M4: Not Found
A5: 0 | B5: Not Found | C5: Not Found | D5: Not Found | E5: Not Found | F5: Not Found | G5: Not Found | H5: Not Found | I5: Not Found | J5: Not Found | K5: Not Found | L5: Not Found | M5: Not Found
A6: 0 | B6: Not Found | C6: Not Found | D6: Not Found | E6: Not Found | F6: Not Found | G6: Not Found | H6: Not Found | I6: Not Found | J6: Not Found | K6: Not Found | L6: Not Found | M6: Not Found
A7: 0 | B7: Not Found | C7: Not Found | D7: Not Found | E7: Not Found | F7: Not Found | G7: Not Found | H7: Not Found | I7: Not Found | J7: Not Found | K7: Not Found | L7: Not Found | M7: Not Found
A8: 0 | B8: Not Found | C8: Not Found | D8: Not Found | E8: Not Found | F8: Not Found | G8: Not Found | H8: Not Found | I8: Not Found | J8: Not Found | K8: Not Found | L8: Not Found | M8: Not Found
A9: 0 | B9: Not Found | C9: Not Found | D9: Not Found | E9: Not Found | F9: Not Found | G9: Not Found | H9: Not Found | I9: Not Found | J9: Not Found | K9: Not Found | L9: Not Found | M9: Not Found
A10: 0 | B10: Not Found | C10: Not Found | D10: Not Found | E10: Not Found | F10: Not Found | G10: Not Found | H10: Not Found | I10: Not Found | J10: Not Found | K10: Not Found | L10: Not Found | M10: Not Found
A11: 0 | B11: Not Found | C11: Not Found | D11: Not Found | E11: Not Found | F11: Not Found | G11: Not Found | H11: Not Found | I11: Not Found | J11: Not Found | K11: Not Found | L11: Not Found | M11: Not Found
A12: 0 | B12: Not Found | C12: Not Found | D12: Not Found | E12: Not Found | F12: Not Found | G12: Not Found | H12: Not Found | I12: Not Found | J12: Not Found | K12: Not Found | L12: Not Found | M12: Not Found
A13: 0 | B13: Not Found | C13: Not Found | D13: Not Found | E13: Not Found | F13: Not Found | G13: Not Found | H13: Not Found | I13: Not Found | J13: Not Found | K13: Not Found | L13: Not Found | M13: Not Found
... A62: 0 | B62: Not Found | C62: Not Found | D62: Not Found | E62: Not Found | F62: Not Found | G62: Not Found | H62: Not Found | I62: Not Found | J62: Not Found | K62: Not Found | L62: Not Found | M62: Not Found
A63: Salter Bros Balfour Hotel | B63: New Farm | C63: AAPT | D63: Voice Number Inventory | E63: Number Range | F63: 37 BALFOUR ST NEW FARM QLD 4005 | G63: 0 | H63: Not Found | I63: 0 | J63: 0 | K63: 0 | L63: Not Found | M63: Not Found
A64: Salter Bros Balfour Hotel | B64: New Farm | C64: AAPT | D64: Voice Number Inventory | E64: Number Range | F64: 37 BALFOUR ST NEW FARM QLD 4005 | G64: 0 | H64: Not Found | I64: 0 | J64: 0 | K64: 0 | L64: Not Found | M64: Not Found
A65: Salter Bros Balfour Hotel | B65: New Farm | C65: AAPT | D65: Voice Number Inventory | E65: Number Range | F65: 37 BALFOUR ST NEW FARM QLD 4005 | G65: 0 | H65: Not Found | I65: 0 | J65: 0 | K65: 0 | L65: Not Found | M65: Not Found
A66: Salter Bros Balfour Hotel | B66: New Farm | C66: AAPT | D66: Voice Number Inventory | E66: Number Range | F66: 37 BALFOUR ST NEW FARM QLD 4005 | G66: 0 | H66: Not Found | I66: 0 | J66: 0 | K66: 0 | L66: Not Found | M66: Not Found
A67: 0 | B67: Not Found | C67: Not Found | D67: Not Found | E67: Not Found | F67: Not Found | G67: Not Found | H67: Not Found | I67: Not Found | J67: Not Found | K67: Not Found | L67: Not Found | M67: Not Found
A68: 0 | B68: Not Found | C68: Not Found | D68: Not Found | E68: Not Found | F68: Not Found | G68: Not Found | H68: Not Found | I68: Not Found | J68: Not Found | K68: Not Found | L68: Not Found | M68: Not Found
A69: 0 | B69: Not Found | C69: Not Found | D69: Not Found | E69: Not Found | F69: Not Found | G69: Not Found | H69: Not Found | I69: Not Found | J69: Not Found | K69: Not Found | L69: Not Found | M69: Not Found
A70: 0 | B70: Not Found | C70: Not Found | D70: Not Found | E70: Not Found | F70: Not Found | G70: Not Found | H70: Not Found | I70: Not Found | J70: Not Found | K70: Not Found | L70: Not Found | M70: Not Found
A71: Solahart Brisbane | B71: Darra | C71: AAPT | D71: Voice Number Inventory | E71: Number Range | F71: 0 | G71: 0 | H71: Not Found | I71: 0 | J71: 0 | K71: 0 | L71: Not Found | M71: Not Found
A72: 0 | B72: Not Found | C72: Not Found | D72: Not Found | E72: Not Found | F72: Not Found | G72: Not Found | H72: Not Found | I72: Not Found | J72: Not Found | K72: Not Found | L72: Not Found | M72: Not Found
A73: 0 | B73: Not Found | C73: Not Found | D73: Not Found | E73: Not Found | F73: Not Found | G73: Not Found | H73: Not Found | I73: Not Found | J73: Not Found | K73: Not Found | L73: Not Found | M73: Not Found
A74: 0 | B74: Not Found | C74: Not Found | D74: Not Found | E74: Not Found | F74: Not Found | G74: Not Found | H74: Not Found | I74: Not Found | J74: Not Found | K74: Not Found | L74: Not Found | M74: Not Found
A75: 0 | B75: Not Found | C75: Not Found | D75: Not Found | E75: Not Found | F75: Not Found | G75: Not Found | H75: Not Found | I75: Not Found | J75: Not Found | K75: Not Found | L75: Not Found | M75: Not Found
A76: 0 | B76: Not Found | C76: Not Found | D76: Not Found | E76: Not Found | F76: Not Found | G76: Not Found | H76: Not Found | I76: Not Found | J76: Not Found | K76: Not Found | L76: Not Found | M76: Not Found
A77: 0 | B77: Not Found | C77: Not Found | D77: Not Found | E77: Not Found | F77: Not Found | G77: Not Found | H77: Not Found | I77: Not Found | J77: Not Found | K77: Not Found | L77: Not Found | M77: Not Found
A78: 0 | B78: Not Found | C78: Not Found | D78: Not Found | E78: Not Found | F78: Not Found | G78: Not Found | H78: Not Found | I78: Not Found | J78: Not Found | K78: Not Found | L78: Not Found | M78: Not Found
A79: 0 | B79: Not Found | C79: Not Found | D79: Not Found | E79: Not Found | F79: Not Found | G79: Not Found | H79: Not Found | I79: Not Found | J79: Not Found | K79: Not Found | L79: Not Found | M79: Not Found
A80: 0 | B80: Not Found | C80: Not Found | D80: Not Found | E80: Not Found | F80: Not Found | G80: Not Found | H80: Not Found | I80: Not Found | J80: Not Found | K80: Not Found | L80: Not Found | M80: Not Found
A81: 0 | B81: Not Found | C81: Not Found | D81: Not Found | E81: Not Found | F81: Not Found | G81: Not Found | H81: Not Found | I81: Not Found | J81: Not Found | K81: Not Found | L81: Not Found | M81: Not Found
A82: 0 | B82: Not Found | C82: Not Found | D82: Not Found | E82: Not Found | F82: Not Found | G82: Not Found | H82: Not Found | I82: Not Found | J82: Not Found | K82: Not Found | L82: Not Found | M82: Not Found
A83: 0 | B83: Not Found | C83: Not Found | D83: Not Found | E83: Not Found | F83: Not Found | G83: Not Found | H83: Not Found | I83: Not Found | J83: Not Found | K83: Not Found | L83: Not Found | M83: Not Found
... A284: 0 | B284: Not Found | C284: Not Found | D284: Not Found | E284: Not Found | F284: Not Found | G284: Not Found | H284: Not Found | I284: Not Found | J284: Not Found | K284: Not Found | L284: Not Found | M284: Not Found
A285: Emergency Medicine Foundation | B285: Level 1D, 60 Enterprise Place , TINGALPA QLD 4174 | C285: Vocus SIT | D285: Voice Service | E285: 0731128668 | F285: IP Tel Order - Smile Tel - 05/07/2024 Voice (5 Mbps) - Level 1D, 60 Enterprise Place , TINGALPA QLD 4173 | G285: Not Found | H285: Not Found | I285: Not Found | J285: Not Found | K285: 45603 | L285: Not Found | M285: Not Found
A286: 0 | B286: Not Found | C286: Not Found | D286: Not Found | E286: Not Found | F286: Not Found | G286: Not Found | H286: Not Found | I286: Not Found | J286: Not Found | K286: Not Found | L286: Not Found | M286: Not Found
A287: Red Roo Australia | B287: Level 1D, 60 Enterprise Place, Tingalpa QLD 4174 | C287: Vocus SIT | D287: Voice Service | E287: 0732558755 0731534563 0736330230 0731534561 | F287: IP Tel Order - Smile Tel - 18/04/2024 Voice (5 Mbps) - Level 1D, 60 Enterprise Place, Tingalpa QLD 4173 | G287: Not Found | H287: Not Found | I287: Not Found | J287: Not Found | K287: 13/06/2024 | L287: Not Found | M287: Not Found
A288: Swara | B288: Level 1D, 60 Enterprise Place, Tingalpa QLD 4174 | C288: Vocus SIT | D288: Voice Service | E288: 0733914119 0733910900 0733910922 | F288: IP Tel Order - Smile Tel - 03/04/2024 - 591822 - SWARA porting Voice (5 Mbps) - Level 1D, 60 Enterprise Place, Tingalpa QLD 4173 | G288: Not Found | H288: Not Found | I288: Not Found | J288: Not Found | K288: 45329 | L288: Not Found | M288: Not Found
...

Sheet Data Feed
A1: Client Name | B1: Client Contact | C1: Client Site | D1: Service Provider | E1: Service Type 1 | F1: Service Type 2 | G1: Service Type 3 | H1: Service Type 4 | I1: Service Type 5 | J1: Connection ID | K1: Contract Term | L1: Contract Start Date | M1: Contract End Date | N1: Billing Gateway
A2: {=_xlfn.VSTACK('AAPT ExDa'!B2:B99,'ABB ExDa'!A2:A186,'Vocus SIT ExDa'!B2:B155,'Telstra ExDa'!B2:B311,'Vocus RVC ExDa'!C2:C156,'Exetel ExDa'!C2:C16,'Fusion ExDa'!B2:B16,'Infinet ExDa'!C2:C15)} -> ASG | B2: =IFERROR(VLOOKUP(A2,'Exetel ExDa'!$C$2:$N$14,4,FALSE),"No Data") -> No Data | C2: =IFERROR(VLOOKUP($A2,'AAPT ExDa'!$B$2:$U$99, 2,FALSE), IFERROR(VLOOKUP($A2,'ABB ExDa'!$A$2:$N$184, 2,FALSE), IFERROR(VLOOKUP($A2,'Vocus SIT ExDa'!$B$2:$J$173, 7,FALSE), IFERROR(VLOOKUP($A2,'Telstra ExDa'!$B$2:$K$310, 2,FALSE), IFERROR(VLOOKUP($A2,'Vocus RVC ExDa'!$C$2:$R$155, 3,FALSE), IFERROR(VLOOKUP($A2,'Fusion ExDa'!$B$2:$D$16, 2,FALSE), IFERROR(VLOOKUP($A2,'Exetel ExDa'!$C$2:$N$14, 2,FALSE), IFERROR(VLOOKUP($A2,'Infinet ExDa'!$B$2:$E$14, 2,FALSE), "Not Found")))))))) -> ASG Pinkenba | D2: =IFERROR(VLOOKUP($A2,'AAPT ExDa'!$B$2:$U$99, 15,FALSE), IFERROR(VLOOKUP($A2,'ABB ExDa'!$A$2:$N$184, 4,FALSE), IFERROR(VLOOKUP($A2,'Vocus SIT ExDa'!$B$2:$J$173, 5,FALSE), IFERROR(VLOOKUP($A2,'Telstra ExDa'!$B$2:$K$310, 8,FALSE), IFERROR(VLOOKUP($A2,'Vocus RVC ExDa'!$C$2:$R$155, 6,FALSE), IFERROR(VLOOKUP($A2,'Fusion ExDa'!$B$2:$D$16, 4,FALSE), IFERROR(VLOOKUP($A2,'Exetel ExDa'!$C$2:$N$14, 3,FALSE), IFERROR(VLOOKUP($A2,'Infinet ExDa'!$B$2:$E$14, 3,FALSE), "Not Found")))))))) -> AAPT | E2: =IFERROR(VLOOKUP($A2,'AAPT ExDa'!$B$2:$U$99, 3,FALSE), IFERROR(VLOOKUP($A2,'ABB ExDa'!$A$2:$N$184, 5,FALSE), IFERROR(VLOOKUP($A2,'Vocus SIT ExDa'!$B$2:$J$173, 2,FALSE), IFERROR(VLOOKUP($A2,'Telstra ExDa'!$B$2:$K$310, 4,FALSE), IFERROR(VLOOKUP($A2,'Vocus RVC ExDa'!$C$2:$R$155, 8,FALSE), IFERROR(VLOOKUP($A2,'Fusion ExDa'!$B$2:$D$16, 4,FALSE), IFERROR(VLOOKUP($A2,'Exetel ExDa'!$C$2:$N$14, 5,FALSE), IFERROR(VLOOKUP($A2,'Infinet ExDa'!$B$2:$E$14, 3,FALSE), "Not Found")))))))) -> IP-Line | F2: =IFERROR(VLOOKUP($A2,'AAPT ExDa'!$B$2:$U$99, 4,FALSE), IFERROR(VLOOKUP($A2,'ABB ExDa'!$A$2:$N$184, 6,FALSE), IFERROR(VLOOKUP($A2,'Vocus SIT ExDa'!$B$2:$J$173, 3,FALSE), IFERROR(VLOOKUP($A2,'Telstra ExDa'!$B$2:$K$310, 5,FALSE), IFERROR(VLOOKUP($A2,'Vocus RVC ExDa'!$C$2:$R$155, 9,FALSE), IFERROR(VLOOKUP($A2,'Fusion ExDa'!$B$2:$D$16, 0,FALSE), IFERROR(VLOOKUP($A2,'Exetel ExDa'!$C$2:$N$14, 6,FALSE), IFERROR(VLOOKUP($A2,'Infinet ExDa'!$B$2:$E$14, 0,FALSE), "Not Found")))))))) -> IP-Line Link | G2: =IFERROR(VLOOKUP($A2,'AAPT ExDa'!$B$2:$U$99, 5,FALSE), IFERROR(VLOOKUP($A2,'ABB ExDa'!$A$2:$N$184, 8,FALSE), IFERROR(VLOOKUP($A2,'Vocus SIT ExDa'!$B$2:$J$173, 6,FALSE), IFERROR(VLOOKUP($A2,'Telstra ExDa'!$B$2:$K$310, 0,FALSE), IFERROR(VLOOKUP($A2,'Vocus RVC ExDa'!$C$2:$R$155, 15,FALSE), IFERROR(VLOOKUP($A2,'Fusion ExDa'!$B$2:$D$16, 0,FALSE), IFERROR(VLOOKUP($A2,'Exetel ExDa'!$C$2:$N$14, 7,FALSE), IFERROR(VLOOKUP($A2,'Infinet ExDa'!$B$2:$E$14, 0,FALSE), "Not Found")))))))) -> Connecting IP-Line 6023265 to Access 100827488 | H2: =IFERROR(VLOOKUP($A2,'AAPT ExDa'!$B$2:$U$99, 6,FALSE), IFERROR(VLOOKUP($A2,'ABB ExDa'!$A$2:$N$184, 0,FALSE), IFERROR(VLOOKUP($A2,'Vocus SIT ExDa'!$B$2:$J$173, 0,FALSE), IFERROR(VLOOKUP($A2,'Telstra ExDa'!$B$2:$K$310, 0,FALSE), IFERROR(VLOOKUP($A2,'Vocus RVC ExDa'!$C$2:$R$155, 16,FALSE), IFERROR(VLOOKUP($A2,'Fusion ExDa'!$B$2:$D$16, 0,FALSE), IFERROR(VLOOKUP($A2,'Exetel ExDa'!$C$2:$N$14, 0,FALSE), IFERROR(VLOOKUP($A2,'Infinet ExDa'!$B$2:$E$14, 0,FALSE), "Not Found")))))))) -> Up to 100/40Mbps; AVC ID:AVC000161725867 | I2: =IFERROR(VLOOKUP($A2,'AAPT ExDa'!$B$2:$U$99, 0,FALSE), IFERROR(VLOOKUP($A2,'ABB ExDa'!$A$2:$N$184, 0,FALSE), IFERROR(VLOOKUP($A2,'Vocus SIT ExDa'!$B$2:$J$173, 0,FALSE), IFERROR(VLOOKUP($A2,'Telstra ExDa'!$B$2:$K$310, 0,FALSE), IFERROR(VLOOKUP($A2,'Vocus RVC ExDa'!$C$2:$R$155, 0,FALSE), IFERROR(VLOOKUP($A2,'Fusion ExDa'!$B$2:$D$16, 0,FALSE), IFERROR(VLOOKUP($A2,'Exetel ExDa'!$C$2:$N$14, 8,FALSE), IFERROR(VLOOKUP($A2,'Infinet ExDa'!$B$2:$E$14, 0,FALSE), "Not Found")))))))) -> Not Found | J2: =IFERROR(VLOOKUP($A2,'AAPT ExDa'!$B$2:$U$99, 7,FALSE), IFERROR(VLOOKUP($A2,'ABB ExDa'!$A$2:$N$184, 2,FALSE), IFERROR(VLOOKUP($A2,'Vocus SIT ExDa'!$B$2:$J$173, 0,FALSE), IFERROR(VLOOKUP($A2,'Telstra ExDa'!$B$2:$K$310, 7,FALSE), IFERROR(VLOOKUP($A2,'Vocus RVC ExDa'!$C$2:$R$155, 2,FALSE), IFERROR(VLOOKUP($A2,'Fusion ExDa'!$B$2:$D$16, 3,FALSE), IFERROR(VLOOKUP($A2,'Exetel ExDa'!$C$2:$N$14, 0,FALSE), IFERROR(VLOOKUP($A2,'Infinet ExDa'!$B$2:$E$14, 0,FALSE), "Not Found")))))))) -> AVC000161725867 | K2: =IFERROR(VLOOKUP($A2,'AAPT ExDa'!$B$2:$U$99, 12,FALSE), IFERROR(VLOOKUP($A2,'ABB ExDa'!$A$2:$N$184, 0,FALSE), IFERROR(VLOOKUP($A2,'Vocus SIT ExDa'!$B$2:$J$173, 0,FALSE), IFERROR(VLOOKUP($A2,'Telstra ExDa'!$B$2:$K$310, 0,FALSE), IFERROR(VLOOKUP($A2,'Vocus RVC ExDa'!$C$2:$R$155, 0,FALSE), IFERROR(VLOOKUP($A2,'Fusion ExDa'!$B$2:$D$16, 0,FALSE), IFERROR(VLOOKUP($A2,'Exetel ExDa'!$C$2:$N$14, 12,FALSE), IFERROR(VLOOKUP($A2,'Infinet ExDa'!$B$2:$E$14, 0,FALSE), "Not Found")))))))) -> 24 Months | L2: =IFERROR(VLOOKUP($A2,'AAPT ExDa'!$B$2:$U$99, 11,FALSE), IFERROR(VLOOKUP($A2,'ABB ExDa'!$A$2:$N$184, 9,FALSE), IFERROR(VLOOKUP($A2,'Vocus SIT ExDa'!$B$2:$J$173, 8,FALSE), IFERROR(VLOOKUP($A2,'Telstra ExDa'!$B$2:$K$310, 0,FALSE), IFERROR(VLOOKUP($A2,'Vocus RVC ExDa'!$C$2:$R$155, 0,FALSE), IFERROR(VLOOKUP($A2,'Fusion ExDa'!$B$2:$D$16, 0,FALSE), IFERROR(VLOOKUP($A2,'Exetel ExDa'!$C$2:$N$14, 9,FALSE), IFERROR(VLOOKUP($A2,'Infinet ExDa'!$B$2:$E$14, 0,FALSE), "Not Found")))))))) -> 45047 | M2: =IFERROR(VLOOKUP($A2,'AAPT ExDa'!$B$2:$U$99, 0,FALSE), IFERROR(VLOOKUP($A2,'ABB ExDa'!$A$2:$N$184, 0,FALSE), IFERROR(VLOOKUP($A2,'Vocus SIT ExDa'!$B$2:$J$173, 0,FALSE), IFERROR(VLOOKUP($A2,'Telstra ExDa'!$B$2:$K$310, 0,FALSE), IFERROR(VLOOKUP($A2,'Vocus RVC ExDa'!$C$2:$R$155, 0,FALSE), IFERROR(VLOOKUP($A2,'Fusion ExDa'!$B$2:$D$16, 0,FALSE), IFERROR(VLOOKUP($A2,'Exetel ExDa'!$C$2:$N$14, 11,FALSE), IFERROR(VLOOKUP($A2,'Infinet ExDa'!$B$2:$E$14, 0,FALSE), "Not Found")))))))) -> Not Found | N2: =IFERROR(VLOOKUP($A2,'AAPT ExDa'!$B$2:$U$99, 0,FALSE), IFERROR(VLOOKUP($A2,'ABB ExDa'!$A$2:$N$184, 13,FALSE), IFERROR(VLOOKUP($A2,'Vocus SIT ExDa'!$B$2:$J$173, 0,FALSE), IFERROR(VLOOKUP($A2,'Telstra ExDa'!$B$2:$K$310, 0,FALSE), IFERROR(VLOOKUP($A2,'Vocus RVC ExDa'!$C$2:$R$155, 0,FALSE), IFERROR(VLOOKUP($A2,'Fusion ExDa'!$B$2:$D$16, 0,FALSE), IFERROR(VLOOKUP($A2,'Exetel ExDa'!$C$2:$N$14, 0,FALSE), IFERROR(VLOOKUP($A2,'Infinet ExDa'!$B$2:$E$14, 0,FALSE), "Not Found")))))))) -> Not Found
A3: ASG | B3: =IFERROR(VLOOKUP(A3,'Exetel ExDa'!$C$2:$N$14,4,FALSE),"No Data") -> No Data | C3: =IFERROR(VLOOKUP(A3,'AAPT ExDa'!$B$2:$U$99, 2,FALSE), IFERROR(VLOOKUP(A3,'ABB ExDa'!$A$2:$N$184, 2,FALSE), IFERROR(VLOOKUP(A3,'Vocus SIT ExDa'!$B$2:$J$173, 7,FALSE), IFERROR(VLOOKUP(A3,'Telstra ExDa'!$B$2:$K$310, 2,FALSE), IFERROR(VLOOKUP(A3,'Vocus RVC ExDa'!$C$2:$R$155, 3,FALSE), IFERROR(VLOOKUP(A3,'Fusion ExDa'!$B$2:$D$16, 2,FALSE), IFERROR(VLOOKUP(A3,'Exetel ExDa'!$C$2:$N$14, 2,FALSE), IFERROR(VLOOKUP(A3,'Infinet ExDa'!$B$2:$E$14, 2,FALSE), "Not Found")))))))) -> ASG Pinkenba | D3: =IFERROR(VLOOKUP($A3,'AAPT ExDa'!$B$2:$U$99, 15,FALSE), IFERROR(VLOOKUP($A3,'ABB ExDa'!$A$2:$N$184, 4,FALSE), IFERROR(VLOOKUP($A3,'Vocus SIT ExDa'!$B$2:$J$173, 5,FALSE), IFERROR(VLOOKUP($A3,'Telstra ExDa'!$B$2:$K$310, 8,FALSE), IFERROR(VLOOKUP($A3,'Vocus RVC ExDa'!$C$2:$R$155, 6,FALSE), IFERROR(VLOOKUP($A3,'Fusion ExDa'!$B$2:$D$16, 4,FALSE), IFERROR(VLOOKUP($A3,'Exetel ExDa'!$C$2:$N$14, 3,FALSE), IFERROR(VLOOKUP($A3,'Infinet ExDa'!$B$2:$E$14, 3,FALSE), "Not Found")))))))) -> AAPT | E3: =IFERROR(VLOOKUP($A3,'AAPT ExDa'!$B$2:$U$99, 3,FALSE), IFERROR(VLOOKUP($A3,'ABB ExDa'!$A$2:$N$184, 5,FALSE), IFERROR(VLOOKUP($A3,'Vocus SIT ExDa'!$B$2:$J$173, 2,FALSE), IFERROR(VLOOKUP($A3,'Telstra ExDa'!$B$2:$K$310, 4,FALSE), IFERROR(VLOOKUP($A3,'Vocus RVC ExDa'!$C$2:$R$155, 8,FALSE), IFERROR(VLOOKUP($A3,'Fusion ExDa'!$B$2:$D$16, 4,FALSE), IFERROR(VLOOKUP($A3,'Exetel ExDa'!$C$2:$N$14, 5,FALSE), IFERROR(VLOOKUP($A3,'Infinet ExDa'!$B$2:$E$14, 3,FALSE), "Not Found")))))))) -> IP-Line | F3: =IFERROR(VLOOKUP($A3,'AAPT ExDa'!$B$2:$U$99, 4,FALSE), IFERROR(VLOOKUP($A3,'ABB ExDa'!$A$2:$N$184, 6,FALSE), IFERROR(VLOOKUP($A3,'Vocus SIT ExDa'!$B$2:$J$173, 3,FALSE), IFERROR(VLOOKUP($A3,'Telstra ExDa'!$B$2:$K$310, 5,FALSE), IFERROR(VLOOKUP($A3,'Vocus RVC ExDa'!$C$2:$R$155, 9,FALSE), IFERROR(VLOOKUP($A3,'Fusion ExDa'!$B$2:$D$16, 0,FALSE), IFERROR(VLOOKUP($A3,'Exetel ExDa'!$C$2:$N$14, 6,FALSE), IFERROR(VLOOKUP($A3,'Infinet ExDa'!$B$2:$E$14, 0,FALSE), "Not Found")))))))) -> IP-Line Link | G3: =IFERROR(VLOOKUP($A3,'AAPT ExDa'!$B$2:$U$99, 5,FALSE), IFERROR(VLOOKUP($A3,'ABB ExDa'!$A$2:$N$184, 8,FALSE), IFERROR(VLOOKUP($A3,'Vocus SIT ExDa'!$B$2:$J$173, 6,FALSE), IFERROR(VLOOKUP($A3,'Telstra ExDa'!$B$2:$K$310, 0,FALSE), IFERROR(VLOOKUP($A3,'Vocus RVC ExDa'!$C$2:$R$155, 15,FALSE), IFERROR(VLOOKUP($A3,'Fusion ExDa'!$B$2:$D$16, 0,FALSE), IFERROR(VLOOKUP($A3,'Exetel ExDa'!$C$2:$N$14, 7,FALSE), IFERROR(VLOOKUP($A3,'Infinet ExDa'!$B$2:$E$14, 0,FALSE), "Not Found")))))))) -> Connecting IP-Line 6023265 to Access 100827488 | H3: =IFERROR(VLOOKUP($A3,'AAPT ExDa'!$B$2:$U$99, 6,FALSE), IFERROR(VLOOKUP($A3,'ABB ExDa'!$A$2:$N$184, 0,FALSE), IFERROR(VLOOKUP($A3,'Vocus SIT ExDa'!$B$2:$J$173, 0,FALSE), IFERROR(VLOOKUP($A3,'Telstra ExDa'!$B$2:$K$310, 0,FALSE), IFERROR(VLOOKUP($A3,'Vocus RVC ExDa'!$C$2:$R$155, 16,FALSE), IFERROR(VLOOKUP($A3,'Fusion ExDa'!$B$2:$D$16, 0,FALSE), IFERROR(VLOOKUP($A3,'Exetel ExDa'!$C$2:$N$14, 0,FALSE), IFERROR(VLOOKUP($A3,'Infinet ExDa'!$B$2:$E$14, 0,FALSE), "Not Found")))))))) -> Up to 100/40Mbps; AVC ID:AVC000161725867 | I3: =IFERROR(VLOOKUP($A3,'AAPT ExDa'!$B$2:$U$99, 0,FALSE), IFERROR(VLOOKUP($A3,'ABB ExDa'!$A$2:$N$184, 0,FALSE), IFERROR(VLOOKUP($A3,'Vocus SIT ExDa'!$B$2:$J$173, 0,FALSE), IFERROR(VLOOKUP($A3,'Telstra ExDa'!$B$2:$K$310, 0,FALSE), IFERROR(VLOOKUP($A3,'Vocus RVC ExDa'!$C$2:$R$155, 0,FALSE), IFERROR(VLOOKUP($A3,'Fusion ExDa'!$B$2:$D$16, 0,FALSE), IFERROR(VLOOKUP($A3,'Exetel ExDa'!$C$2:$N$14, 8,FALSE), IFERROR(VLOOKUP($A3,'Infinet ExDa'!$B$2:$E$14, 0,FALSE), "Not Found")))))))) -> Not Found | J3: =IFERROR(VLOOKUP($A3,'AAPT ExDa'!$B$2:$U$99, 7,FALSE), IFERROR(VLOOKUP($A3,'ABB ExDa'!$A$2:$N$184, 2,FALSE), IFERROR(VLOOKUP($A3,'Vocus SIT ExDa'!$B$2:$J$173, 0,FALSE), IFERROR(VLOOKUP($A3,'Telstra ExDa'!$B$2:$K$310, 7,FALSE), IFERROR(VLOOKUP($A3,'Vocus RVC ExDa'!$C$2:$R$155, 2,FALSE), IFERROR(VLOOKUP($A3,'Fusion ExDa'!$B$2:$D$16, 3,FALSE), IFERROR(VLOOKUP($A3,'Exetel ExDa'!$C$2:$N$14, 0,FALSE), IFERROR(VLOOKUP($A3,'Infinet ExDa'!$B$2:$E$14, 0,FALSE), "Not Found")))))))) -> AVC000161725867 | K3: =IFERROR(VLOOKUP($A3,'AAPT ExDa'!$B$2:$U$99, 12,FALSE), IFERROR(VLOOKUP($A3,'ABB ExDa'!$A$2:$N$184, 0,FALSE), IFERROR(VLOOKUP($A3,'Vocus SIT ExDa'!$B$2:$J$173, 0,FALSE), IFERROR(VLOOKUP($A3,'Telstra ExDa'!$B$2:$K$310, 0,FALSE), IFERROR(VLOOKUP($A3,'Vocus RVC ExDa'!$C$2:$R$155, 0,FALSE), IFERROR(VLOOKUP($A3,'Fusion ExDa'!$B$2:$D$16, 0,FALSE), IFERROR(VLOOKUP($A3,'Exetel ExDa'!$C$2:$N$14, 12,FALSE), IFERROR(VLOOKUP($A3,'Infinet ExDa'!$B$2:$E$14, 0,FALSE), "Not Found")))))))) -> 24 Months | L3: =IFERROR(VLOOKUP($A3,'AAPT ExDa'!$B$2:$U$99, 11,FALSE), IFERROR(VLOOKUP($A3,'ABB ExDa'!$A$2:$N$184, 9,FALSE), IFERROR(VLOOKUP($A3,'Vocus SIT ExDa'!$B$2:$J$173, 8,FALSE), IFERROR(VLOOKUP($A3,'Telstra ExDa'!$B$2:$K$310, 0,FALSE), IFERROR(VLOOKUP($A3,'Vocus RVC ExDa'!$C$2:$R$155, 0,FALSE), IFERROR(VLOOKUP($A3,'Fusion ExDa'!$B$2:$D$16, 0,FALSE), IFERROR(VLOOKUP($A3,'Exetel ExDa'!$C$2:$N$14, 9,FALSE), IFERROR(VLOOKUP($A3,'Infinet ExDa'!$B$2:$E$14, 0,FALSE), "Not Found")))))))) -> 45047 | M3: =IFERROR(VLOOKUP($A3,'AAPT ExDa'!$B$2:$U$99, 0,FALSE), IFERROR(VLOOKUP($A3,'ABB ExDa'!$A$2:$N$184, 0,FALSE), IFERROR(VLOOKUP($A3,'Vocus SIT ExDa'!$B$2:$J$173, 0,FALSE), IFERROR(VLOOKUP($A3,'Telstra ExDa'!$B$2:$K$310, 0,FALSE), IFERROR(VLOOKUP($A3,'Vocus RVC ExDa'!$C$2:$R$155, 0,FALSE), IFERROR(VLOOKUP($A3,'Fusion ExDa'!$B$2:$D$16, 0,FALSE), IFERROR(VLOOKUP($A3,'Exetel ExDa'!$C$2:$N$14, 11,FALSE), IFERROR(VLOOKUP($A3,'Infinet ExDa'!$B$2:$E$14, 0,FALSE), "Not Found")))))))) -> Not Found | N3: =IFERROR(VLOOKUP($A3,'AAPT ExDa'!$B$2:$U$99, 0,FALSE), IFERROR(VLOOKUP($A3,'ABB ExDa'!$A$2:$N$184, 13,FALSE), IFERROR(VLOOKUP($A3,'Vocus SIT ExDa'!$B$2:$J$173, 0,FALSE), IFERROR(VLOOKUP($A3,'Telstra ExDa'!$B$2:$K$310, 0,FALSE), IFERROR(VLOOKUP($A3,'Vocus RVC ExDa'!$C$2:$R$155, 0,FALSE), IFERROR(VLOOKUP($A3,'Fusion ExDa'!$B$2:$D$16, 0,FALSE), IFERROR(VLOOKUP($A3,'Exetel ExDa'!$C$2:$N$14, 0,FALSE), IFERROR(VLOOKUP($A3,'Infinet ExDa'!$B$2:$E$14, 0,FALSE), "Not Found")))))))) -> Not Found
A4: ASG | B4: =IFERROR(VLOOKUP(A4,'Exetel ExDa'!$C$2:$N$14,4,FALSE),"No Data") -> No Data | C4: =IFERROR(VLOOKUP(A4,'AAPT ExDa'!$B$2:$U$99, 2,FALSE), IFERROR(VLOOKUP(A4,'ABB ExDa'!$A$2:$N$184, 2,FALSE), IFERROR(VLOOKUP(A4,'Vocus SIT ExDa'!$B$2:$J$173, 7,FALSE), IFERROR(VLOOKUP(A4,'Telstra ExDa'!$B$2:$K$310, 2,FALSE), IFERROR(VLOOKUP(A4,'Vocus RVC ExDa'!$C$2:$R$155, 3,FALSE), IFERROR(VLOOKUP(A4,'Fusion ExDa'!$B$2:$D$16, 2,FALSE), IFERROR(VLOOKUP(A4,'Exetel ExDa'!$C$2:$N$14, 2,FALSE), IFERROR(VLOOKUP(A4,'Infinet ExDa'!$B$2:$E$14, 2,FALSE), "Not Found")))))))) -> ASG Pinkenba | D4: =IFERROR(VLOOKUP($A4,'AAPT ExDa'!$B$2:$U$99, 15,FALSE), IFERROR(VLOOKUP($A4,'ABB ExDa'!$A$2:$N$184, 4,FALSE), IFERROR(VLOOKUP($A4,'Vocus SIT ExDa'!$B$2:$J$173, 5,FALSE), IFERROR(VLOOKUP($A4,'Telstra ExDa'!$B$2:$K$310, 8,FALSE), IFERROR(VLOOKUP($A4,'Vocus RVC ExDa'!$C$2:$R$155, 6,FALSE), IFERROR(VLOOKUP($A4,'Fusion ExDa'!$B$2:$D$16, 4,FALSE), IFERROR(VLOOKUP($A4,'Exetel ExDa'!$C$2:$N$14, 3,FALSE), IFERROR(VLOOKUP($A4,'Infinet ExDa'!$B$2:$E$14, 3,FALSE), "Not Found")))))))) -> AAPT | E4: =IFERROR(VLOOKUP($A4,'AAPT ExDa'!$B$2:$U$99, 3,FALSE), IFERROR(VLOOKUP($A4,'ABB ExDa'!$A$2:$N$184, 5,FALSE), IFERROR(VLOOKUP($A4,'Vocus SIT ExDa'!$B$2:$J$173, 2,FALSE), IFERROR(VLOOKUP($A4,'Telstra ExDa'!$B$2:$K$310, 4,FALSE), IFERROR(VLOOKUP($A4,'Vocus RVC ExDa'!$C$2:$R$155, 8,FALSE), IFERROR(VLOOKUP($A4,'Fusion ExDa'!$B$2:$D$16, 4,FALSE), IFERROR(VLOOKUP($A4,'Exetel ExDa'!$C$2:$N$14, 5,FALSE), IFERROR(VLOOKUP($A4,'Infinet ExDa'!$B$2:$E$14, 3,FALSE), "Not Found")))))))) -> IP-Line | F4: =IFERROR(VLOOKUP($A4,'AAPT ExDa'!$B$2:$U$99, 4,FALSE), IFERROR(VLOOKUP($A4,'ABB ExDa'!$A$2:$N$184, 6,FALSE), IFERROR(VLOOKUP($A4,'Vocus SIT ExDa'!$B$2:$J$173, 3,FALSE), IFERROR(VLOOKUP($A4,'Telstra ExDa'!$B$2:$K$310, 5,FALSE), IFERROR(VLOOKUP($A4,'Vocus RVC ExDa'!$C$2:$R$155, 9,FALSE), IFERROR(VLOOKUP($A4,'Fusion ExDa'!$B$2:$D$16, 0,FALSE), IFERROR(VLOOKUP($A4,'Exetel ExDa'!$C$2:$N$14, 6,FALSE), IFERROR(VLOOKUP($A4,'Infinet ExDa'!$B$2:$E$14, 0,FALSE), "Not Found")))))))) -> IP-Line Link | G4: =IFERROR(VLOOKUP($A4,'AAPT ExDa'!$B$2:$U$99, 5,FALSE), IFERROR(VLOOKUP($A4,'ABB ExDa'!$A$2:$N$184, 8,FALSE), IFERROR(VLOOKUP($A4,'Vocus SIT ExDa'!$B$2:$J$173, 6,FALSE), IFERROR(VLOOKUP($A4,'Telstra ExDa'!$B$2:$K$310, 0,FALSE), IFERROR(VLOOKUP($A4,'Vocus RVC ExDa'!$C$2:$R$155, 15,FALSE), IFERROR(VLOOKUP($A4,'Fusion ExDa'!$B$2:$D$16, 0,FALSE), IFERROR(VLOOKUP($A4,'Exetel ExDa'!$C$2:$N$14, 7,FALSE), IFERROR(VLOOKUP($A4,'Infinet ExDa'!$B$2:$E$14, 0,FALSE), "Not Found")))))))) -> Connecting IP-Line 6023265 to Access 100827488 | H4: =IFERROR(VLOOKUP($A4,'AAPT ExDa'!$B$2:$U$99, 6,FALSE), IFERROR(VLOOKUP($A4,'ABB ExDa'!$A$2:$N$184, 0,FALSE), IFERROR(VLOOKUP($A4,'Vocus SIT ExDa'!$B$2:$J$173, 0,FALSE), IFERROR(VLOOKUP($A4,'Telstra ExDa'!$B$2:$K$310, 0,FALSE), IFERROR(VLOOKUP($A4,'Vocus RVC ExDa'!$C$2:$R$155, 16,FALSE), IFERROR(VLOOKUP($A4,'Fusion ExDa'!$B$2:$D$16, 0,FALSE), IFERROR(VLOOKUP($A4,'Exetel ExDa'!$C$2:$N$14, 0,FALSE), IFERROR(VLOOKUP($A4,'Infinet ExDa'!$B$2:$E$14, 0,FALSE), "Not Found")))))))) -> Up to 100/40Mbps; AVC ID:AVC000161725867 | I4: =IFERROR(VLOOKUP($A4,'AAPT ExDa'!$B$2:$U$99, 0,FALSE), IFERROR(VLOOKUP($A4,'ABB ExDa'!$A$2:$N$184, 0,FALSE), IFERROR(VLOOKUP($A4,'Vocus SIT ExDa'!$B$2:$J$173, 0,FALSE), IFERROR(VLOOKUP($A4,'Telstra ExDa'!$B$2:$K$310, 0,FALSE), IFERROR(VLOOKUP($A4,'Vocus RVC ExDa'!$C$2:$R$155, 0,FALSE), IFERROR(VLOOKUP($A4,'Fusion ExDa'!$B$2:$D$16, 0,FALSE), IFERROR(VLOOKUP($A4,'Exetel ExDa'!$C$2:$N$14, 8,FALSE), IFERROR(VLOOKUP($A4,'Infinet ExDa'!$B$2:$E$14, 0,FALSE), "Not Found")))))))) -> Not Found | J4: =IFERROR(VLOOKUP($A4,'AAPT ExDa'!$B$2:$U$99, 7,FALSE), IFERROR(VLOOKUP($A4,'ABB ExDa'!$A$2:$N$184, 2,FALSE), IFERROR(VLOOKUP($A4,'Vocus SIT ExDa'!$B$2:$J$173, 0,FALSE), IFERROR(VLOOKUP($A4,'Telstra ExDa'!$B$2:$K$310, 7,FALSE), IFERROR(VLOOKUP($A4,'Vocus RVC ExDa'!$C$2:$R$155, 2,FALSE), IFERROR(VLOOKUP($A4,'Fusion ExDa'!$B$2:$D$16, 3,FALSE), IFERROR(VLOOKUP($A4,'Exetel ExDa'!$C$2:$N$14, 0,FALSE), IFERROR(VLOOKUP($A4,'Infinet ExDa'!$B$2:$E$14, 0,FALSE), "Not Found")))))))) -> AVC000161725867 | K4: =IFERROR(VLOOKUP($A4,'AAPT ExDa'!$B$2:$U$99, 12,FALSE), IFERROR(VLOOKUP($A4,'ABB ExDa'!$A$2:$N$184, 0,FALSE), IFERROR(VLOOKUP($A4,'Vocus SIT ExDa'!$B$2:$J$173, 0,FALSE), IFERROR(VLOOKUP($A4,'Telstra ExDa'!$B$2:$K$310, 0,FALSE), IFERROR(VLOOKUP($A4,'Vocus RVC ExDa'!$C$2:$R$155, 0,FALSE), IFERROR(VLOOKUP($A4,'Fusion ExDa'!$B$2:$D$16, 0,FALSE), IFERROR(VLOOKUP($A4,'Exetel ExDa'!$C$2:$N$14, 12,FALSE), IFERROR(VLOOKUP($A4,'Infinet ExDa'!$B$2:$E$14, 0,FALSE), "Not Found")))))))) -> 24 Months | L4: =IFERROR(VLOOKUP($A4,'AAPT ExDa'!$B$2:$U$99, 11,FALSE), IFERROR(VLOOKUP($A4,'ABB ExDa'!$A$2:$N$184, 9,FALSE), IFERROR(VLOOKUP($A4,'Vocus SIT ExDa'!$B$2:$J$173, 8,FALSE), IFERROR(VLOOKUP($A4,'Telstra ExDa'!$B$2:$K$310, 0,FALSE), IFERROR(VLOOKUP($A4,'Vocus RVC ExDa'!$C$2:$R$155, 0,FALSE), IFERROR(VLOOKUP($A4,'Fusion ExDa'!$B$2:$D$16, 0,FALSE), IFERROR(VLOOKUP($A4,'Exetel ExDa'!$C$2:$N$14, 9,FALSE), IFERROR(VLOOKUP($A4,'Infinet ExDa'!$B$2:$E$14, 0,FALSE), "Not Found")))))))) -> 45047 | M4: =IFERROR(VLOOKUP($A4,'AAPT ExDa'!$B$2:$U$99, 0,FALSE), IFERROR(VLOOKUP($A4,'ABB ExDa'!$A$2:$N$184, 0,FALSE), IFERROR(VLOOKUP($A4,'Vocus SIT ExDa'!$B$2:$J$173, 0,FALSE), IFERROR(VLOOKUP($A4,'Telstra ExDa'!$B$2:$K$310, 0,FALSE), IFERROR(VLOOKUP($A4,'Vocus RVC ExDa'!$C$2:$R$155, 0,FALSE), IFERROR(VLOOKUP($A4,'Fusion ExDa'!$B$2:$D$16, 0,FALSE), IFERROR(VLOOKUP($A4,'Exetel ExDa'!$C$2:$N$14, 11,FALSE), IFERROR(VLOOKUP($A4,'Infinet ExDa'!$B$2:$E$14, 0,FALSE), "Not Found")))))))) -> Not Found | N4: =IFERROR(VLOOKUP($A4,'AAPT ExDa'!$B$2:$U$99, 0,FALSE), IFERROR(VLOOKUP($A4,'ABB ExDa'!$A$2:$N$184, 13,FALSE), IFERROR(VLOOKUP($A4,'Vocus SIT ExDa'!$B$2:$J$173, 0,FALSE), IFERROR(VLOOKUP($A4,'Telstra ExDa'!$B$2:$K$310, 0,FALSE), IFERROR(VLOOKUP($A4,'Vocus RVC ExDa'!$C$2:$R$155, 0,FALSE), IFERROR(VLOOKUP($A4,'Fusion ExDa'!$B$2:$D$16, 0,FALSE), IFERROR(VLOOKUP($A4,'Exetel ExDa'!$C$2:$N$14, 0,FALSE), IFERROR(VLOOKUP($A4,'Infinet ExDa'!$B$2:$E$14, 0,FALSE), "Not Found")))))))) -> Not Found
A5: ASG | B5: =IFERROR(VLOOKUP(A5,'Exetel ExDa'!$C$2:$N$14,4,FALSE),"No Data") -> No Data | C5: =IFERROR(VLOOKUP(A5,'AAPT ExDa'!$B$2:$U$99, 2,FALSE), IFERROR(VLOOKUP(A5,'ABB ExDa'!$A$2:$N$184, 2,FALSE), IFERROR(VLOOKUP(A5,'Vocus SIT ExDa'!$B$2:$J$173, 7,FALSE), IFERROR(VLOOKUP(A5,'Telstra ExDa'!$B$2:$K$310, 2,FALSE), IFERROR(VLOOKUP(A5,'Vocus RVC ExDa'!$C$2:$R$155, 3,FALSE), IFERROR(VLOOKUP(A5,'Fusion ExDa'!$B$2:$D$16, 2,FALSE), IFERROR(VLOOKUP(A5,'Exetel ExDa'!$C$2:$N$14, 2,FALSE), IFERROR(VLOOKUP(A5,'Infinet ExDa'!$B$2:$E$14, 2,FALSE), "Not Found")))))))) -> ASG Pinkenba | D5: =IFERROR(VLOOKUP($A5,'AAPT ExDa'!$B$2:$U$99, 15,FALSE), IFERROR(VLOOKUP($A5,'ABB ExDa'!$A$2:$N$184, 4,FALSE), IFERROR(VLOOKUP($A5,'Vocus SIT ExDa'!$B$2:$J$173, 5,FALSE), IFERROR(VLOOKUP($A5,'Telstra ExDa'!$B$2:$K$310, 8,FALSE), IFERROR(VLOOKUP($A5,'Vocus RVC ExDa'!$C$2:$R$155, 6,FALSE), IFERROR(VLOOKUP($A5,'Fusion ExDa'!$B$2:$D$16, 4,FALSE), IFERROR(VLOOKUP($A5,'Exetel ExDa'!$C$2:$N$14, 3,FALSE), IFERROR(VLOOKUP($A5,'Infinet ExDa'!$B$2:$E$14, 3,FALSE), "Not Found")))))))) -> AAPT | E5: =IFERROR(VLOOKUP($A5,'AAPT ExDa'!$B$2:$U$99, 3,FALSE), IFERROR(VLOOKUP($A5,'ABB ExDa'!$A$2:$N$184, 5,FALSE), IFERROR(VLOOKUP($A5,'Vocus SIT ExDa'!$B$2:$J$173, 2,FALSE), IFERROR(VLOOKUP($A5,'Telstra ExDa'!$B$2:$K$310, 4,FALSE), IFERROR(VLOOKUP($A5,'Vocus RVC ExDa'!$C$2:$R$155, 8,FALSE), IFERROR(VLOOKUP($A5,'Fusion ExDa'!$B$2:$D$16, 4,FALSE), IFERROR(VLOOKUP($A5,'Exetel ExDa'!$C$2:$N$14, 5,FALSE), IFERROR(VLOOKUP($A5,'Infinet ExDa'!$B$2:$E$14, 3,FALSE), "Not Found")))))))) -> IP-Line | F5: =IFERROR(VLOOKUP($A5,'AAPT ExDa'!$B$2:$U$99, 4,FALSE), IFERROR(VLOOKUP($A5,'ABB ExDa'!$A$2:$N$184, 6,FALSE), IFERROR(VLOOKUP($A5,'Vocus SIT ExDa'!$B$2:$J$173, 3,FALSE), IFERROR(VLOOKUP($A5,'Telstra ExDa'!$B$2:$K$310, 5,FALSE), IFERROR(VLOOKUP($A5,'Vocus RVC ExDa'!$C$2:$R$155, 9,FALSE), IFERROR(VLOOKUP($A5,'Fusion ExDa'!$B$2:$D$16, 0,FALSE), IFERROR(VLOOKUP($A5,'Exetel ExDa'!$C$2:$N$14, 6,FALSE), IFERROR(VLOOKUP($A5,'Infinet ExDa'!$B$2:$E$14, 0,FALSE), "Not Found")))))))) -> IP-Line Link | G5: =IFERROR(VLOOKUP($A5,'AAPT ExDa'!$B$2:$U$99, 5,FALSE), IFERROR(VLOOKUP($A5,'ABB ExDa'!$A$2:$N$184, 8,FALSE), IFERROR(VLOOKUP($A5,'Vocus SIT ExDa'!$B$2:$J$173, 6,FALSE), IFERROR(VLOOKUP($A5,'Telstra ExDa'!$B$2:$K$310, 0,FALSE), IFERROR(VLOOKUP($A5,'Vocus RVC ExDa'!$C$2:$R$155, 15,FALSE), IFERROR(VLOOKUP($A5,'Fusion ExDa'!$B$2:$D$16, 0,FALSE), IFERROR(VLOOKUP($A5,'Exetel ExDa'!$C$2:$N$14, 7,FALSE), IFERROR(VLOOKUP($A5,'Infinet ExDa'!$B$2:$E$14, 0,FALSE), "Not Found")))))))) -> Connecting IP-Line 6023265 to Access 100827488 | H5: =IFERROR(VLOOKUP($A5,'AAPT ExDa'!$B$2:$U$99, 6,FALSE), IFERROR(VLOOKUP($A5,'ABB ExDa'!$A$2:$N$184, 0,FALSE), IFERROR(VLOOKUP($A5,'Vocus SIT ExDa'!$B$2:$J$173, 0,FALSE), IFERROR(VLOOKUP($A5,'Telstra ExDa'!$B$2:$K$310, 0,FALSE), IFERROR(VLOOKUP($A5,'Vocus RVC ExDa'!$C$2:$R$155, 16,FALSE), IFERROR(VLOOKUP($A5,'Fusion ExDa'!$B$2:$D$16, 0,FALSE), IFERROR(VLOOKUP($A5,'Exetel ExDa'!$C$2:$N$14, 0,FALSE), IFERROR(VLOOKUP($A5,'Infinet ExDa'!$B$2:$E$14, 0,FALSE), "Not Found")))))))) -> Up to 100/40Mbps; AVC ID:AVC000161725867 | I5: =IFERROR(VLOOKUP($A5,'AAPT ExDa'!$B$2:$U$99, 0,FALSE), IFERROR(VLOOKUP($A5,'ABB ExDa'!$A$2:$N$184, 0,FALSE), IFERROR(VLOOKUP($A5,'Vocus SIT ExDa'!$B$2:$J$173, 0,FALSE), IFERROR(VLOOKUP($A5,'Telstra ExDa'!$B$2:$K$310, 0,FALSE), IFERROR(VLOOKUP($A5,'Vocus RVC ExDa'!$C$2:$R$155, 0,FALSE), IFERROR(VLOOKUP($A5,'Fusion ExDa'!$B$2:$D$16, 0,FALSE), IFERROR(VLOOKUP($A5,'Exetel ExDa'!$C$2:$N$14, 8,FALSE), IFERROR(VLOOKUP($A5,'Infinet ExDa'!$B$2:$E$14, 0,FALSE), "Not Found")))))))) -> Not Found | J5: =IFERROR(VLOOKUP($A5,'AAPT ExDa'!$B$2:$U$99, 7,FALSE), IFERROR(VLOOKUP($A5,'ABB ExDa'!$A$2:$N$184, 2,FALSE), IFERROR(VLOOKUP($A5,'Vocus SIT ExDa'!$B$2:$J$173, 0,FALSE), IFERROR(VLOOKUP($A5,'Telstra ExDa'!$B$2:$K$310, 7,FALSE), IFERROR(VLOOKUP($A5,'Vocus RVC ExDa'!$C$2:$R$155, 2,FALSE), IFERROR(VLOOKUP($A5,'Fusion ExDa'!$B$2:$D$16, 3,FALSE), IFERROR(VLOOKUP($A5,'Exetel ExDa'!$C$2:$N$14, 0,FALSE), IFERROR(VLOOKUP($A5,'Infinet ExDa'!$B$2:$E$14, 0,FALSE), "Not Found")))))))) -> AVC000161725867 | K5: =IFERROR(VLOOKUP($A5,'AAPT ExDa'!$B$2:$U$99, 12,FALSE), IFERROR(VLOOKUP($A5,'ABB ExDa'!$A$2:$N$184, 0,FALSE), IFERROR(VLOOKUP($A5,'Vocus SIT ExDa'!$B$2:$J$173, 0,FALSE), IFERROR(VLOOKUP($A5,'Telstra ExDa'!$B$2:$K$310, 0,FALSE), IFERROR(VLOOKUP($A5,'Vocus RVC ExDa'!$C$2:$R$155, 0,FALSE), IFERROR(VLOOKUP($A5,'Fusion ExDa'!$B$2:$D$16, 0,FALSE), IFERROR(VLOOKUP($A5,'Exetel ExDa'!$C$2:$N$14, 12,FALSE), IFERROR(VLOOKUP($A5,'Infinet ExDa'!$B$2:$E$14, 0,FALSE), "Not Found")))))))) -> 24 Months | L5: =IFERROR(VLOOKUP($A5,'AAPT ExDa'!$B$2:$U$99, 11,FALSE), IFERROR(VLOOKUP($A5,'ABB ExDa'!$A$2:$N$184, 9,FALSE), IFERROR(VLOOKUP($A5,'Vocus SIT ExDa'!$B$2:$J$173, 8,FALSE), IFERROR(VLOOKUP($A5,'Telstra ExDa'!$B$2:$K$310, 0,FALSE), IFERROR(VLOOKUP($A5,'Vocus RVC ExDa'!$C$2:$R$155, 0,FALSE), IFERROR(VLOOKUP($A5,'Fusion ExDa'!$B$2:$D$16, 0,FALSE), IFERROR(VLOOKUP($A5,'Exetel ExDa'!$C$2:$N$14, 9,FALSE), IFERROR(VLOOKUP($A5,'Infinet ExDa'!$B$2:$E$14, 0,FALSE), "Not Found")))))))) -> 45047 | M5: =IFERROR(VLOOKUP($A5,'AAPT ExDa'!$B$2:$U$99, 0,FALSE), IFERROR(VLOOKUP($A5,'ABB ExDa'!$A$2:$N$184, 0,FALSE), IFERROR(VLOOKUP($A5,'Vocus SIT ExDa'!$B$2:$J$173, 0,FALSE), IFERROR(VLOOKUP($A5,'Telstra ExDa'!$B$2:$K$310, 0,FALSE), IFERROR(VLOOKUP($A5,'Vocus RVC ExDa'!$C$2:$R$155, 0,FALSE), IFERROR(VLOOKUP($A5,'Fusion ExDa'!$B$2:$D$16, 0,FALSE), IFERROR(VLOOKUP($A5,'Exetel ExDa'!$C$2:$N$14, 11,FALSE), IFERROR(VLOOKUP($A5,'Infinet ExDa'!$B$2:$E$14, 0,FALSE), "Not Found")))))))) -> Not Found | N5: =IFERROR(VLOOKUP($A5,'AAPT ExDa'!$B$2:$U$99, 0,FALSE), IFERROR(VLOOKUP($A5,'ABB ExDa'!$A$2:$N$184, 13,FALSE), IFERROR(VLOOKUP($A5,'Vocus SIT ExDa'!$B$2:$J$173, 0,FALSE), IFERROR(VLOOKUP($A5,'Telstra ExDa'!$B$2:$K$310, 0,FALSE), IFERROR(VLOOKUP($A5,'Vocus RVC ExDa'!$C$2:$R$155, 0,FALSE), IFERROR(VLOOKUP($A5,'Fusion ExDa'!$B$2:$D$16, 0,FALSE), IFERROR(VLOOKUP($A5,'Exetel ExDa'!$C$2:$N$14, 0,FALSE), IFERROR(VLOOKUP($A5,'Infinet ExDa'!$B$2:$E$14, 0,FALSE), "Not Found")))))))) -> Not Found
A6: Auriga Group | B6: =IFERROR(VLOOKUP(A6,'Exetel ExDa'!$C$2:$N$14,4,FALSE),"No Data") -> No Data | C6: =IFERROR(VLOOKUP(A6,'AAPT ExDa'!$B$2:$U$99, 2,FALSE), IFERROR(VLOOKUP(A6,'ABB ExDa'!$A$2:$N$184, 2,FALSE), IFERROR(VLOOKUP(A6,'Vocus SIT ExDa'!$B$2:$J$173, 7,FALSE), IFERROR(VLOOKUP(A6,'Telstra ExDa'!$B$2:$K$310, 2,FALSE), IFERROR(VLOOKUP(A6,'Vocus RVC ExDa'!$C$2:$R$155, 3,FALSE), IFERROR(VLOOKUP(A6,'Fusion ExDa'!$B$2:$D$16, 2,FALSE), IFERROR(VLOOKUP(A6,'Exetel ExDa'!$C$2:$N$14, 2,FALSE), IFERROR(VLOOKUP(A6,'Infinet ExDa'!$B$2:$E$14, 2,FALSE), "Not Found")))))))) -> Albion | D6: =IFERROR(VLOOKUP($A6,'AAPT ExDa'!$B$2:$U$99, 15,FALSE), IFERROR(VLOOKUP($A6,'ABB ExDa'!$A$2:$N$184, 4,FALSE), IFERROR(VLOOKUP($A6,'Vocus SIT ExDa'!$B$2:$J$173, 5,FALSE), IFERROR(VLOOKUP($A6,'Telstra ExDa'!$B$2:$K$310, 8,FALSE), IFERROR(VLOOKUP($A6,'Vocus RVC ExDa'!$C$2:$R$155, 6,FALSE), IFERROR(VLOOKUP($A6,'Fusion ExDa'!$B$2:$D$16, 4,FALSE), IFERROR(VLOOKUP($A6,'Exetel ExDa'!$C$2:$N$14, 3,FALSE), IFERROR(VLOOKUP($A6,'Infinet ExDa'!$B$2:$E$14, 3,FALSE), "Not Found")))))))) -> AAPT | E6: =IFERROR(VLOOKUP($A6,'AAPT ExDa'!$B$2:$U$99, 3,FALSE), IFERROR(VLOOKUP($A6,'ABB ExDa'!$A$2:$N$184, 5,FALSE), IFERROR(VLOOKUP($A6,'Vocus SIT ExDa'!$B$2:$J$173, 2,FALSE), IFERROR(VLOOKUP($A6,'Telstra ExDa'!$B$2:$K$310, 4,FALSE), IFERROR(VLOOKUP($A6,'Vocus RVC ExDa'!$C$2:$R$155, 8,FALSE), IFERROR(VLOOKUP($A6,'Fusion ExDa'!$B$2:$D$16, 4,FALSE), IFERROR(VLOOKUP($A6,'Exetel ExDa'!$C$2:$N$14, 5,FALSE), IFERROR(VLOOKUP($A6,'Infinet ExDa'!$B$2:$E$14, 3,FALSE), "Not Found")))))))) -> FAST Fibre | F6: =IFERROR(VLOOKUP($A6,'AAPT ExDa'!$B$2:$U$99, 4,FALSE), IFERROR(VLOOKUP($A6,'ABB ExDa'!$A$2:$N$184, 6,FALSE), IFERROR(VLOOKUP($A6,'Vocus SIT ExDa'!$B$2:$J$173, 3,FALSE), IFERROR(VLOOKUP($A6,'Telstra ExDa'!$B$2:$K$310, 5,FALSE), IFERROR(VLOOKUP($A6,'Vocus RVC ExDa'!$C$2:$R$155, 9,FALSE), IFERROR(VLOOKUP($A6,'Fusion ExDa'!$B$2:$D$16, 0,FALSE), IFERROR(VLOOKUP($A6,'Exetel ExDa'!$C$2:$N$14, 6,FALSE), IFERROR(VLOOKUP($A6,'Infinet ExDa'!$B$2:$E$14, 0,FALSE), "Not Found")))))))) -> FAST Fibre (NTU) | G6: =IFERROR(VLOOKUP($A6,'AAPT ExDa'!$B$2:$U$99, 5,FALSE), IFERROR(VLOOKUP($A6,'ABB ExDa'!$A$2:$N$184, 8,FALSE), IFERROR(VLOOKUP($A6,'Vocus SIT ExDa'!$B$2:$J$173, 6,FALSE), IFERROR(VLOOKUP($A6,'Telstra ExDa'!$B$2:$K$310, 0,FALSE), IFERROR(VLOOKUP($A6,'Vocus RVC ExDa'!$C$2:$R$155, 15,FALSE), IFERROR(VLOOKUP($A6,'Fusion ExDa'!$B$2:$D$16, 0,FALSE), IFERROR(VLOOKUP($A6,'Exetel ExDa'!$C$2:$N$14, 7,FALSE), IFERROR(VLOOKUP($A6,'Infinet ExDa'!$B$2:$E$14, 0,FALSE), "Not Found")))))))) -> 0 | H6: =IFERROR(VLOOKUP($A6,'AAPT ExDa'!$B$2:$U$99, 6,FALSE), IFERROR(VLOOKUP($A6,'ABB ExDa'!$A$2:$N$184, 0,FALSE), IFERROR(VLOOKUP($A6,'Vocus SIT ExDa'!$B$2:$J$173, 0,FALSE), IFERROR(VLOOKUP($A6,'Telstra ExDa'!$B$2:$K$310, 0,FALSE), IFERROR(VLOOKUP($A6,'Vocus RVC ExDa'!$C$2:$R$155, 16,FALSE), IFERROR(VLOOKUP($A6,'Fusion ExDa'!$B$2:$D$16, 0,FALSE), IFERROR(VLOOKUP($A6,'Exetel ExDa'!$C$2:$N$14, 0,FALSE), IFERROR(VLOOKUP($A6,'Infinet ExDa'!$B$2:$E$14, 0,FALSE), "Not Found")))))))) -> 400 Mbps; 36 Months | I6: =IFERROR(VLOOKUP($A6,'AAPT ExDa'!$B$2:$U$99, 0,FALSE), IFERROR(VLOOKUP($A6,'ABB ExDa'!$A$2:$N$184, 0,FALSE), IFERROR(VLOOKUP($A6,'Vocus SIT ExDa'!$B$2:$J$173, 0,FALSE), IFERROR(VLOOKUP($A6,'Telstra ExDa'!$B$2:$K$310, 0,FALSE), IFERROR(VLOOKUP($A6,'Vocus RVC ExDa'!$C$2:$R$155, 0,FALSE), IFERROR(VLOOKUP($A6,'Fusion ExDa'!$B$2:$D$16, 0,FALSE), IFERROR(VLOOKUP($A6,'Exetel ExDa'!$C$2:$N$14, 8,FALSE), IFERROR(VLOOKUP($A6,'Infinet ExDa'!$B$2:$E$14, 0,FALSE), "Not Found")))))))) -> Not Found | J6: =IFERROR(VLOOKUP($A6,'AAPT ExDa'!$B$2:$U$99, 7,FALSE), IFERROR(VLOOKUP($A6,'ABB ExDa'!$A$2:$N$184, 2,FALSE), IFERROR(VLOOKUP($A6,'Vocus SIT ExDa'!$B$2:$J$173, 0,FALSE), IFERROR(VLOOKUP($A6,'Telstra ExDa'!$B$2:$K$310, 7,FALSE), IFERROR(VLOOKUP($A6,'Vocus RVC ExDa'!$C$2:$R$155, 2,FALSE), IFERROR(VLOOKUP($A6,'Fusion ExDa'!$B$2:$D$16, 3,FALSE), IFERROR(VLOOKUP($A6,'Exetel ExDa'!$C$2:$N$14, 0,FALSE), IFERROR(VLOOKUP($A6,'Infinet ExDa'!$B$2:$E$14, 0,FALSE), "Not Found")))))))) -> 0 | K6: =IFERROR(VLOOKUP($A6,'AAPT ExDa'!$B$2:$U$99, 12,FALSE), IFERROR(VLOOKUP($A6,'ABB ExDa'!$A$2:$N$184, 0,FALSE), IFERROR(VLOOKUP($A6,'Vocus SIT ExDa'!$B$2:$J$173, 0,FALSE), IFERROR(VLOOKUP($A6,'Telstra ExDa'!$B$2:$K$310, 0,FALSE), IFERROR(VLOOKUP($A6,'Vocus RVC ExDa'!$C$2:$R$155, 0,FALSE), IFERROR(VLOOKUP($A6,'Fusion ExDa'!$B$2:$D$16, 0,FALSE), IFERROR(VLOOKUP($A6,'Exetel ExDa'!$C$2:$N$14, 12,FALSE), IFERROR(VLOOKUP($A6,'Infinet ExDa'!$B$2:$E$14, 0,FALSE), "Not Found")))))))) -> 36 Months | L6: =IFERROR(VLOOKUP($A6,'AAPT ExDa'!$B$2:$U$99, 11,FALSE), IFERROR(VLOOKUP($A6,'ABB ExDa'!$A$2:$N$184, 9,FALSE), IFERROR(VLOOKUP($A6,'Vocus SIT ExDa'!$B$2:$J$173, 8,FALSE), IFERROR(VLOOKUP($A6,'Telstra ExDa'!$B$2:$K$310, 0,FALSE), IFERROR(VLOOKUP($A6,'Vocus RVC ExDa'!$C$2:$R$155, 0,FALSE), IFERROR(VLOOKUP($A6,'Fusion ExDa'!$B$2:$D$16, 0,FALSE), IFERROR(VLOOKUP($A6,'Exetel ExDa'!$C$2:$N$14, 9,FALSE), IFERROR(VLOOKUP($A6,'Infinet ExDa'!$B$2:$E$14, 0,FALSE), "Not Found")))))))) -> 15/04/2022 | M6: =IFERROR(VLOOKUP($A6,'AAPT ExDa'!$B$2:$U$99, 0,FALSE), IFERROR(VLOOKUP($A6,'ABB ExDa'!$A$2:$N$184, 0,FALSE), IFERROR(VLOOKUP($A6,'Vocus SIT ExDa'!$B$2:$J$173, 0,FALSE), IFERROR(VLOOKUP($A6,'Telstra ExDa'!$B$2:$K$310, 0,FALSE), IFERROR(VLOOKUP($A6,'Vocus RVC ExDa'!$C$2:$R$155, 0,FALSE), IFERROR(VLOOKUP($A6,'Fusion ExDa'!$B$2:$D$16, 0,FALSE), IFERROR(VLOOKUP($A6,'Exetel ExDa'!$C$2:$N$14, 11,FALSE), IFERROR(VLOOKUP($A6,'Infinet ExDa'!$B$2:$E$14, 0,FALSE), "Not Found")))))))) -> Not Found | N6: =IFERROR(VLOOKUP($A6,'AAPT ExDa'!$B$2:$U$99, 0,FALSE), IFERROR(VLOOKUP($A6,'ABB ExDa'!$A$2:$N$184, 13,FALSE), IFERROR(VLOOKUP($A6,'Vocus SIT ExDa'!$B$2:$J$173, 0,FALSE), IFERROR(VLOOKUP($A6,'Telstra ExDa'!$B$2:$K$310, 0,FALSE), IFERROR(VLOOKUP($A6,'Vocus RVC ExDa'!$C$2:$R$155, 0,FALSE), IFERROR(VLOOKUP($A6,'Fusion ExDa'!$B$2:$D$16, 0,FALSE), IFERROR(VLOOKUP($A6,'Exetel ExDa'!$C$2:$N$14, 0,FALSE), IFERROR(VLOOKUP($A6,'Infinet ExDa'!$B$2:$E$14, 0,FALSE), "Not Found")))))))) -> Not Found
A7: Auriga Group | B7: =IFERROR(VLOOKUP(A7,'Exetel ExDa'!$C$2:$N$14,4,FALSE),"No Data") -> No Data | C7: =IFERROR(VLOOKUP(A7,'AAPT ExDa'!$B$2:$U$99, 2,FALSE), IFERROR(VLOOKUP(A7,'ABB ExDa'!$A$2:$N$184, 2,FALSE), IFERROR(VLOOKUP(A7,'Vocus SIT ExDa'!$B$2:$J$173, 7,FALSE), IFERROR(VLOOKUP(A7,'Telstra ExDa'!$B$2:$K$310, 2,FALSE), IFERROR(VLOOKUP(A7,'Vocus RVC ExDa'!$C$2:$R$155, 3,FALSE), IFERROR(VLOOKUP(A7,'Fusion ExDa'!$B$2:$D$16, 2,FALSE), IFERROR(VLOOKUP(A7,'Exetel ExDa'!$C$2:$N$14, 2,FALSE), IFERROR(VLOOKUP(A7,'Infinet ExDa'!$B$2:$E$14, 2,FALSE), "Not Found")))))))) -> Albion | D7: =IFERROR(VLOOKUP($A7,'AAPT ExDa'!$B$2:$U$99, 15,FALSE), IFERROR(VLOOKUP($A7,'ABB ExDa'!$A$2:$N$184, 4,FALSE), IFERROR(VLOOKUP($A7,'Vocus SIT ExDa'!$B$2:$J$173, 5,FALSE), IFERROR(VLOOKUP($A7,'Telstra ExDa'!$B$2:$K$310, 8,FALSE), IFERROR(VLOOKUP($A7,'Vocus RVC ExDa'!$C$2:$R$155, 6,FALSE), IFERROR(VLOOKUP($A7,'Fusion ExDa'!$B$2:$D$16, 4,FALSE), IFERROR(VLOOKUP($A7,'Exetel ExDa'!$C$2:$N$14, 3,FALSE), IFERROR(VLOOKUP($A7,'Infinet ExDa'!$B$2:$E$14, 3,FALSE), "Not Found")))))))) -> AAPT | E7: =IFERROR(VLOOKUP($A7,'AAPT ExDa'!$B$2:$U$99, 3,FALSE), IFERROR(VLOOKUP($A7,'ABB ExDa'!$A$2:$N$184, 5,FALSE), IFERROR(VLOOKUP($A7,'Vocus SIT ExDa'!$B$2:$J$173, 2,FALSE), IFERROR(VLOOKUP($A7,'Telstra ExDa'!$B$2:$K$310, 4,FALSE), IFERROR(VLOOKUP($A7,'Vocus RVC ExDa'!$C$2:$R$155, 8,FALSE), IFERROR(VLOOKUP($A7,'Fusion ExDa'!$B$2:$D$16, 4,FALSE), IFERROR(VLOOKUP($A7,'Exetel ExDa'!$C$2:$N$14, 5,FALSE), IFERROR(VLOOKUP($A7,'Infinet ExDa'!$B$2:$E$14, 3,FALSE), "Not Found")))))))) -> FAST Fibre | F7: =IFERROR(VLOOKUP($A7,'AAPT ExDa'!$B$2:$U$99, 4,FALSE), IFERROR(VLOOKUP($A7,'ABB ExDa'!$A$2:$N$184, 6,FALSE), IFERROR(VLOOKUP($A7,'Vocus SIT ExDa'!$B$2:$J$173, 3,FALSE), IFERROR(VLOOKUP($A7,'Telstra ExDa'!$B$2:$K$310, 5,FALSE), IFERROR(VLOOKUP($A7,'Vocus RVC ExDa'!$C$2:$R$155, 9,FALSE), IFERROR(VLOOKUP($A7,'Fusion ExDa'!$B$2:$D$16, 0,FALSE), IFERROR(VLOOKUP($A7,'Exetel ExDa'!$C$2:$N$14, 6,FALSE), IFERROR(VLOOKUP($A7,'Infinet ExDa'!$B$2:$E$14, 0,FALSE), "Not Found")))))))) -> FAST Fibre (NTU) | G7: =IFERROR(VLOOKUP($A7,'AAPT ExDa'!$B$2:$U$99, 5,FALSE), IFERROR(VLOOKUP($A7,'ABB ExDa'!$A$2:$N$184, 8,FALSE), IFERROR(VLOOKUP($A7,'Vocus SIT ExDa'!$B$2:$J$173, 6,FALSE), IFERROR(VLOOKUP($A7,'Telstra ExDa'!$B$2:$K$310, 0,FALSE), IFERROR(VLOOKUP($A7,'Vocus RVC ExDa'!$C$2:$R$155, 15,FALSE), IFERROR(VLOOKUP($A7,'Fusion ExDa'!$B$2:$D$16, 0,FALSE), IFERROR(VLOOKUP($A7,'Exetel ExDa'!$C$2:$N$14, 7,FALSE), IFERROR(VLOOKUP($A7,'Infinet ExDa'!$B$2:$E$14, 0,FALSE), "Not Found")))))))) -> 0 | H7: =IFERROR(VLOOKUP($A7,'AAPT ExDa'!$B$2:$U$99, 6,FALSE), IFERROR(VLOOKUP($A7,'ABB ExDa'!$A$2:$N$184, 0,FALSE), IFERROR(VLOOKUP($A7,'Vocus SIT ExDa'!$B$2:$J$173, 0,FALSE), IFERROR(VLOOKUP($A7,'Telstra ExDa'!$B$2:$K$310, 0,FALSE), IFERROR(VLOOKUP($A7,'Vocus RVC ExDa'!$C$2:$R$155, 16,FALSE), IFERROR(VLOOKUP($A7,'Fusion ExDa'!$B$2:$D$16, 0,FALSE), IFERROR(VLOOKUP($A7,'Exetel ExDa'!$C$2:$N$14, 0,FALSE), IFERROR(VLOOKUP($A7,'Infinet ExDa'!$B$2:$E$14, 0,FALSE), "Not Found")))))))) -> 400 Mbps; 36 Months | I7: =IFERROR(VLOOKUP($A7,'AAPT ExDa'!$B$2:$U$99, 0,FALSE), IFERROR(VLOOKUP($A7,'ABB ExDa'!$A$2:$N$184, 0,FALSE), IFERROR(VLOOKUP($A7,'Vocus SIT ExDa'!$B$2:$J$173, 0,FALSE), IFERROR(VLOOKUP($A7,'Telstra ExDa'!$B$2:$K$310, 0,FALSE), IFERROR(VLOOKUP($A7,'Vocus RVC ExDa'!$C$2:$R$155, 0,FALSE), IFERROR(VLOOKUP($A7,'Fusion ExDa'!$B$2:$D$16, 0,FALSE), IFERROR(VLOOKUP($A7,'Exetel ExDa'!$C$2:$N$14, 8,FALSE), IFERROR(VLOOKUP($A7,'Infinet ExDa'!$B$2:$E$14, 0,FALSE), "Not Found")))))))) -> Not Found | J7: =IFERROR(VLOOKUP($A7,'AAPT ExDa'!$B$2:$U$99, 7,FALSE), IFERROR(VLOOKUP($A7,'ABB ExDa'!$A$2:$N$184, 2,FALSE), IFERROR(VLOOKUP($A7,'Vocus SIT ExDa'!$B$2:$J$173, 0,FALSE), IFERROR(VLOOKUP($A7,'Telstra ExDa'!$B$2:$K$310, 7,FALSE), IFERROR(VLOOKUP($A7,'Vocus RVC ExDa'!$C$2:$R$155, 2,FALSE), IFERROR(VLOOKUP($A7,'Fusion ExDa'!$B$2:$D$16, 3,FALSE), IFERROR(VLOOKUP($A7,'Exetel ExDa'!$C$2:$N$14, 0,FALSE), IFERROR(VLOOKUP($A7,'Infinet ExDa'!$B$2:$E$14, 0,FALSE), "Not Found")))))))) -> 0 | K7: =IFERROR(VLOOKUP($A7,'AAPT ExDa'!$B$2:$U$99, 12,FALSE), IFERROR(VLOOKUP($A7,'ABB ExDa'!$A$2:$N$184, 0,FALSE), IFERROR(VLOOKUP($A7,'Vocus SIT ExDa'!$B$2:$J$173, 0,FALSE), IFERROR(VLOOKUP($A7,'Telstra ExDa'!$B$2:$K$310, 0,FALSE), IFERROR(VLOOKUP($A7,'Vocus RVC ExDa'!$C$2:$R$155, 0,FALSE), IFERROR(VLOOKUP($A7,'Fusion ExDa'!$B$2:$D$16, 0,FALSE), IFERROR(VLOOKUP($A7,'Exetel ExDa'!$C$2:$N$14, 12,FALSE), IFERROR(VLOOKUP($A7,'Infinet ExDa'!$B$2:$E$14, 0,FALSE), "Not Found")))))))) -> 36 Months | L7: =IFERROR(VLOOKUP($A7,'AAPT ExDa'!$B$2:$U$99, 11,FALSE), IFERROR(VLOOKUP($A7,'ABB ExDa'!$A$2:$N$184, 9,FALSE), IFERROR(VLOOKUP($A7,'Vocus SIT ExDa'!$B$2:$J$173, 8,FALSE), IFERROR(VLOOKUP($A7,'Telstra ExDa'!$B$2:$K$310, 0,FALSE), IFERROR(VLOOKUP($A7,'Vocus RVC ExDa'!$C$2:$R$155, 0,FALSE), IFERROR(VLOOKUP($A7,'Fusion ExDa'!$B$2:$D$16, 0,FALSE), IFERROR(VLOOKUP($A7,'Exetel ExDa'!$C$2:$N$14, 9,FALSE), IFERROR(VLOOKUP($A7,'Infinet ExDa'!$B$2:$E$14, 0,FALSE), "Not Found")))))))) -> 15/04/2022 | M7: =IFERROR(VLOOKUP($A7,'AAPT ExDa'!$B$2:$U$99, 0,FALSE), IFERROR(VLOOKUP($A7,'ABB ExDa'!$A$2:$N$184, 0,FALSE), IFERROR(VLOOKUP($A7,'Vocus SIT ExDa'!$B$2:$J$173, 0,FALSE), IFERROR(VLOOKUP($A7,'Telstra ExDa'!$B$2:$K$310, 0,FALSE), IFERROR(VLOOKUP($A7,'Vocus RVC ExDa'!$C$2:$R$155, 0,FALSE), IFERROR(VLOOKUP($A7,'Fusion ExDa'!$B$2:$D$16, 0,FALSE), IFERROR(VLOOKUP($A7,'Exetel ExDa'!$C$2:$N$14, 11,FALSE), IFERROR(VLOOKUP($A7,'Infinet ExDa'!$B$2:$E$14, 0,FALSE), "Not Found")))))))) -> Not Found | N7: =IFERROR(VLOOKUP($A7,'AAPT ExDa'!$B$2:$U$99, 0,FALSE), IFERROR(VLOOKUP($A7,'ABB ExDa'!$A$2:$N$184, 13,FALSE), IFERROR(VLOOKUP($A7,'Vocus SIT ExDa'!$B$2:$J$173, 0,FALSE), IFERROR(VLOOKUP($A7,'Telstra ExDa'!$B$2:$K$310, 0,FALSE), IFERROR(VLOOKUP($A7,'Vocus RVC ExDa'!$C$2:$R$155, 0,FALSE), IFERROR(VLOOKUP($A7,'Fusion ExDa'!$B$2:$D$16, 0,FALSE), IFERROR(VLOOKUP($A7,'Exetel ExDa'!$C$2:$N$14, 0,FALSE), IFERROR(VLOOKUP($A7,'Infinet ExDa'!$B$2:$E$14, 0,FALSE), "Not Found")))))))) -> Not Found
A8: Auriga Group | B8: =IFERROR(VLOOKUP(A8,'Exetel ExDa'!$C$2:$N$14,4,FALSE),"No Data") -> No Data | C8: =IFERROR(VLOOKUP(A8,'AAPT ExDa'!$B$2:$U$99, 2,FALSE), IFERROR(VLOOKUP(A8,'ABB ExDa'!$A$2:$N$184, 2,FALSE), IFERROR(VLOOKUP(A8,'Vocus SIT ExDa'!$B$2:$J$173, 7,FALSE), IFERROR(VLOOKUP(A8,'Telstra ExDa'!$B$2:$K$310, 2,FALSE), IFERROR(VLOOKUP(A8,'Vocus RVC ExDa'!$C$2:$R$155, 3,FALSE), IFERROR(VLOOKUP(A8,'Fusion ExDa'!$B$2:$D$16, 2,FALSE), IFERROR(VLOOKUP(A8,'Exetel ExDa'!$C$2:$N$14, 2,FALSE), IFERROR(VLOOKUP(A8,'Infinet ExDa'!$B$2:$E$14, 2,FALSE), "Not Found")))))))) -> Albion | D8: =IFERROR(VLOOKUP($A8,'AAPT ExDa'!$B$2:$U$99, 15,FALSE), IFERROR(VLOOKUP($A8,'ABB ExDa'!$A$2:$N$184, 4,FALSE), IFERROR(VLOOKUP($A8,'Vocus SIT ExDa'!$B$2:$J$173, 5,FALSE), IFERROR(VLOOKUP($A8,'Telstra ExDa'!$B$2:$K$310, 8,FALSE), IFERROR(VLOOKUP($A8,'Vocus RVC ExDa'!$C$2:$R$155, 6,FALSE), IFERROR(VLOOKUP($A8,'Fusion ExDa'!$B$2:$D$16, 4,FALSE), IFERROR(VLOOKUP($A8,'Exetel ExDa'!$C$2:$N$14, 3,FALSE), IFERROR(VLOOKUP($A8,'Infinet ExDa'!$B$2:$E$14, 3,FALSE), "Not Found")))))))) -> AAPT | E8: =IFERROR(VLOOKUP($A8,'AAPT ExDa'!$B$2:$U$99, 3,FALSE), IFERROR(VLOOKUP($A8,'ABB ExDa'!$A$2:$N$184, 5,FALSE), IFERROR(VLOOKUP($A8,'Vocus SIT ExDa'!$B$2:$J$173, 2,FALSE), IFERROR(VLOOKUP($A8,'Telstra ExDa'!$B$2:$K$310, 4,FALSE), IFERROR(VLOOKUP($A8,'Vocus RVC ExDa'!$C$2:$R$155, 8,FALSE), IFERROR(VLOOKUP($A8,'Fusion ExDa'!$B$2:$D$16, 4,FALSE), IFERROR(VLOOKUP($A8,'Exetel ExDa'!$C$2:$N$14, 5,FALSE), IFERROR(VLOOKUP($A8,'Infinet ExDa'!$B$2:$E$14, 3,FALSE), "Not Found")))))))) -> FAST Fibre | F8: =IFERROR(VLOOKUP($A8,'AAPT ExDa'!$B$2:$U$99, 4,FALSE), IFERROR(VLOOKUP($A8,'ABB ExDa'!$A$2:$N$184, 6,FALSE), IFERROR(VLOOKUP($A8,'Vocus SIT ExDa'!$B$2:$J$173, 3,FALSE), IFERROR(VLOOKUP($A8,'Telstra ExDa'!$B$2:$K$310, 5,FALSE), IFERROR(VLOOKUP($A8,'Vocus RVC ExDa'!$C$2:$R$155, 9,FALSE), IFERROR(VLOOKUP($A8,'Fusion ExDa'!$B$2:$D$16, 0,FALSE), IFERROR(VLOOKUP($A8,'Exetel ExDa'!$C$2:$N$14, 6,FALSE), IFERROR(VLOOKUP($A8,'Infinet ExDa'!$B$2:$E$14, 0,FALSE), "Not Found")))))))) -> FAST Fibre (NTU) | G8: =IFERROR(VLOOKUP($A8,'AAPT ExDa'!$B$2:$U$99, 5,FALSE), IFERROR(VLOOKUP($A8,'ABB ExDa'!$A$2:$N$184, 8,FALSE), IFERROR(VLOOKUP($A8,'Vocus SIT ExDa'!$B$2:$J$173, 6,FALSE), IFERROR(VLOOKUP($A8,'Telstra ExDa'!$B$2:$K$310, 0,FALSE), IFERROR(VLOOKUP($A8,'Vocus RVC ExDa'!$C$2:$R$155, 15,FALSE), IFERROR(VLOOKUP($A8,'Fusion ExDa'!$B$2:$D$16, 0,FALSE), IFERROR(VLOOKUP($A8,'Exetel ExDa'!$C$2:$N$14, 7,FALSE), IFERROR(VLOOKUP($A8,'Infinet ExDa'!$B$2:$E$14, 0,FALSE), "Not Found")))))))) -> 0 | H8: =IFERROR(VLOOKUP($A8,'AAPT ExDa'!$B$2:$U$99, 6,FALSE), IFERROR(VLOOKUP($A8,'ABB ExDa'!$A$2:$N$184, 0,FALSE), IFERROR(VLOOKUP($A8,'Vocus SIT ExDa'!$B$2:$J$173, 0,FALSE), IFERROR(VLOOKUP($A8,'Telstra ExDa'!$B$2:$K$310, 0,FALSE), IFERROR(VLOOKUP($A8,'Vocus RVC ExDa'!$C$2:$R$155, 16,FALSE), IFERROR(VLOOKUP($A8,'Fusion ExDa'!$B$2:$D$16, 0,FALSE), IFERROR(VLOOKUP($A8,'Exetel ExDa'!$C$2:$N$14, 0,FALSE), IFERROR(VLOOKUP($A8,'Infinet ExDa'!$B$2:$E$14, 0,FALSE), "Not Found")))))))) -> 400 Mbps; 36 Months | I8: =IFERROR(VLOOKUP($A8,'AAPT ExDa'!$B$2:$U$99, 0,FALSE), IFERROR(VLOOKUP($A8,'ABB ExDa'!$A$2:$N$184, 0,FALSE), IFERROR(VLOOKUP($A8,'Vocus SIT ExDa'!$B$2:$J$173, 0,FALSE), IFERROR(VLOOKUP($A8,'Telstra ExDa'!$B$2:$K$310, 0,FALSE), IFERROR(VLOOKUP($A8,'Vocus RVC ExDa'!$C$2:$R$155, 0,FALSE), IFERROR(VLOOKUP($A8,'Fusion ExDa'!$B$2:$D$16, 0,FALSE), IFERROR(VLOOKUP($A8,'Exetel ExDa'!$C$2:$N$14, 8,FALSE), IFERROR(VLOOKUP($A8,'Infinet ExDa'!$B$2:$E$14, 0,FALSE), "Not Found")))))))) -> Not Found | J8: =IFERROR(VLOOKUP($A8,'AAPT ExDa'!$B$2:$U$99, 7,FALSE), IFERROR(VLOOKUP($A8,'ABB ExDa'!$A$2:$N$184, 2,FALSE), IFERROR(VLOOKUP($A8,'Vocus SIT ExDa'!$B$2:$J$173, 0,FALSE), IFERROR(VLOOKUP($A8,'Telstra ExDa'!$B$2:$K$310, 7,FALSE), IFERROR(VLOOKUP($A8,'Vocus RVC ExDa'!$C$2:$R$155, 2,FALSE), IFERROR(VLOOKUP($A8,'Fusion ExDa'!$B$2:$D$16, 3,FALSE), IFERROR(VLOOKUP($A8,'Exetel ExDa'!$C$2:$N$14, 0,FALSE), IFERROR(VLOOKUP($A8,'Infinet ExDa'!$B$2:$E$14, 0,FALSE), "Not Found")))))))) -> 0 | K8: =IFERROR(VLOOKUP($A8,'AAPT ExDa'!$B$2:$U$99, 12,FALSE), IFERROR(VLOOKUP($A8,'ABB ExDa'!$A$2:$N$184, 0,FALSE), IFERROR(VLOOKUP($A8,'Vocus SIT ExDa'!$B$2:$J$173, 0,FALSE), IFERROR(VLOOKUP($A8,'Telstra ExDa'!$B$2:$K$310, 0,FALSE), IFERROR(VLOOKUP($A8,'Vocus RVC ExDa'!$C$2:$R$155, 0,FALSE), IFERROR(VLOOKUP($A8,'Fusion ExDa'!$B$2:$D$16, 0,FALSE), IFERROR(VLOOKUP($A8,'Exetel ExDa'!$C$2:$N$14, 12,FALSE), IFERROR(VLOOKUP($A8,'Infinet ExDa'!$B$2:$E$14, 0,FALSE), "Not Found")))))))) -> 36 Months | L8: =IFERROR(VLOOKUP($A8,'AAPT ExDa'!$B$2:$U$99, 11,FALSE), IFERROR(VLOOKUP($A8,'ABB ExDa'!$A$2:$N$184, 9,FALSE), IFERROR(VLOOKUP($A8,'Vocus SIT ExDa'!$B$2:$J$173, 8,FALSE), IFERROR(VLOOKUP($A8,'Telstra ExDa'!$B$2:$K$310, 0,FALSE), IFERROR(VLOOKUP($A8,'Vocus RVC ExDa'!$C$2:$R$155, 0,FALSE), IFERROR(VLOOKUP($A8,'Fusion ExDa'!$B$2:$D$16, 0,FALSE), IFERROR(VLOOKUP($A8,'Exetel ExDa'!$C$2:$N$14, 9,FALSE), IFERROR(VLOOKUP($A8,'Infinet ExDa'!$B$2:$E$14, 0,FALSE), "Not Found")))))))) -> 15/04/2022 | M8: =IFERROR(VLOOKUP($A8,'AAPT ExDa'!$B$2:$U$99, 0,FALSE), IFERROR(VLOOKUP($A8,'ABB ExDa'!$A$2:$N$184, 0,FALSE), IFERROR(VLOOKUP($A8,'Vocus SIT ExDa'!$B$2:$J$173, 0,FALSE), IFERROR(VLOOKUP($A8,'Telstra ExDa'!$B$2:$K$310, 0,FALSE), IFERROR(VLOOKUP($A8,'Vocus RVC ExDa'!$C$2:$R$155, 0,FALSE), IFERROR(VLOOKUP($A8,'Fusion ExDa'!$B$2:$D$16, 0,FALSE), IFERROR(VLOOKUP($A8,'Exetel ExDa'!$C$2:$N$14, 11,FALSE), IFERROR(VLOOKUP($A8,'Infinet ExDa'!$B$2:$E$14, 0,FALSE), "Not Found")))))))) -> Not Found | N8: =IFERROR(VLOOKUP($A8,'AAPT ExDa'!$B$2:$U$99, 0,FALSE), IFERROR(VLOOKUP($A8,'ABB ExDa'!$A$2:$N$184, 13,FALSE), IFERROR(VLOOKUP($A8,'Vocus SIT ExDa'!$B$2:$J$173, 0,FALSE), IFERROR(VLOOKUP($A8,'Telstra ExDa'!$B$2:$K$310, 0,FALSE), IFERROR(VLOOKUP($A8,'Vocus RVC ExDa'!$C$2:$R$155, 0,FALSE), IFERROR(VLOOKUP($A8,'Fusion ExDa'!$B$2:$D$16, 0,FALSE), IFERROR(VLOOKUP($A8,'Exetel ExDa'!$C$2:$N$14, 0,FALSE), IFERROR(VLOOKUP($A8,'Infinet ExDa'!$B$2:$E$14, 0,FALSE), "Not Found")))))))) -> Not Found
A9: Auriga Group | B9: =IFERROR(VLOOKUP(A9,'Exetel ExDa'!$C$2:$N$14,4,FALSE),"No Data") -> No Data | C9: =IFERROR(VLOOKUP(A9,'AAPT ExDa'!$B$2:$U$99, 2,FALSE), IFERROR(VLOOKUP(A9,'ABB ExDa'!$A$2:$N$184, 2,FALSE), IFERROR(VLOOKUP(A9,'Vocus SIT ExDa'!$B$2:$J$173, 7,FALSE), IFERROR(VLOOKUP(A9,'Telstra ExDa'!$B$2:$K$310, 2,FALSE), IFERROR(VLOOKUP(A9,'Vocus RVC ExDa'!$C$2:$R$155, 3,FALSE), IFERROR(VLOOKUP(A9,'Fusion ExDa'!$B$2:$D$16, 2,FALSE), IFERROR(VLOOKUP(A9,'Exetel ExDa'!$C$2:$N$14, 2,FALSE), IFERROR(VLOOKUP(A9,'Infinet ExDa'!$B$2:$E$14, 2,FALSE), "Not Found")))))))) -> Albion | D9: =IFERROR(VLOOKUP($A9,'AAPT ExDa'!$B$2:$U$99, 15,FALSE), IFERROR(VLOOKUP($A9,'ABB ExDa'!$A$2:$N$184, 4,FALSE), IFERROR(VLOOKUP($A9,'Vocus SIT ExDa'!$B$2:$J$173, 5,FALSE), IFERROR(VLOOKUP($A9,'Telstra ExDa'!$B$2:$K$310, 8,FALSE), IFERROR(VLOOKUP($A9,'Vocus RVC ExDa'!$C$2:$R$155, 6,FALSE), IFERROR(VLOOKUP($A9,'Fusion ExDa'!$B$2:$D$16, 4,FALSE), IFERROR(VLOOKUP($A9,'Exetel ExDa'!$C$2:$N$14, 3,FALSE), IFERROR(VLOOKUP($A9,'Infinet ExDa'!$B$2:$E$14, 3,FALSE), "Not Found")))))))) -> AAPT | E9: =IFERROR(VLOOKUP($A9,'AAPT ExDa'!$B$2:$U$99, 3,FALSE), IFERROR(VLOOKUP($A9,'ABB ExDa'!$A$2:$N$184, 5,FALSE), IFERROR(VLOOKUP($A9,'Vocus SIT ExDa'!$B$2:$J$173, 2,FALSE), IFERROR(VLOOKUP($A9,'Telstra ExDa'!$B$2:$K$310, 4,FALSE), IFERROR(VLOOKUP($A9,'Vocus RVC ExDa'!$C$2:$R$155, 8,FALSE), IFERROR(VLOOKUP($A9,'Fusion ExDa'!$B$2:$D$16, 4,FALSE), IFERROR(VLOOKUP($A9,'Exetel ExDa'!$C$2:$N$14, 5,FALSE), IFERROR(VLOOKUP($A9,'Infinet ExDa'!$B$2:$E$14, 3,FALSE), "Not Found")))))))) -> FAST Fibre | F9: =IFERROR(VLOOKUP($A9,'AAPT ExDa'!$B$2:$U$99, 4,FALSE), IFERROR(VLOOKUP($A9,'ABB ExDa'!$A$2:$N$184, 6,FALSE), IFERROR(VLOOKUP($A9,'Vocus SIT ExDa'!$B$2:$J$173, 3,FALSE), IFERROR(VLOOKUP($A9,'Telstra ExDa'!$B$2:$K$310, 5,FALSE), IFERROR(VLOOKUP($A9,'Vocus RVC ExDa'!$C$2:$R$155, 9,FALSE), IFERROR(VLOOKUP($A9,'Fusion ExDa'!$B$2:$D$16, 0,FALSE), IFERROR(VLOOKUP($A9,'Exetel ExDa'!$C$2:$N$14, 6,FALSE), IFERROR(VLOOKUP($A9,'Infinet ExDa'!$B$2:$E$14, 0,FALSE), "Not Found")))))))) -> FAST Fibre (NTU) | G9: =IFERROR(VLOOKUP($A9,'AAPT ExDa'!$B$2:$U$99, 5,FALSE), IFERROR(VLOOKUP($A9,'ABB ExDa'!$A$2:$N$184, 8,FALSE), IFERROR(VLOOKUP($A9,'Vocus SIT ExDa'!$B$2:$J$173, 6,FALSE), IFERROR(VLOOKUP($A9,'Telstra ExDa'!$B$2:$K$310, 0,FALSE), IFERROR(VLOOKUP($A9,'Vocus RVC ExDa'!$C$2:$R$155, 15,FALSE), IFERROR(VLOOKUP($A9,'Fusion ExDa'!$B$2:$D$16, 0,FALSE), IFERROR(VLOOKUP($A9,'Exetel ExDa'!$C$2:$N$14, 7,FALSE), IFERROR(VLOOKUP($A9,'Infinet ExDa'!$B$2:$E$14, 0,FALSE), "Not Found")))))))) -> 0 | H9: =IFERROR(VLOOKUP($A9,'AAPT ExDa'!$B$2:$U$99, 6,FALSE), IFERROR(VLOOKUP($A9,'ABB ExDa'!$A$2:$N$184, 0,FALSE), IFERROR(VLOOKUP($A9,'Vocus SIT ExDa'!$B$2:$J$173, 0,FALSE), IFERROR(VLOOKUP($A9,'Telstra ExDa'!$B$2:$K$310, 0,FALSE), IFERROR(VLOOKUP($A9,'Vocus RVC ExDa'!$C$2:$R$155, 16,FALSE), IFERROR(VLOOKUP($A9,'Fusion ExDa'!$B$2:$D$16, 0,FALSE), IFERROR(VLOOKUP($A9,'Exetel ExDa'!$C$2:$N$14, 0,FALSE), IFERROR(VLOOKUP($A9,'Infinet ExDa'!$B$2:$E$14, 0,FALSE), "Not Found")))))))) -> 400 Mbps; 36 Months | I9: =IFERROR(VLOOKUP($A9,'AAPT ExDa'!$B$2:$U$99, 0,FALSE), IFERROR(VLOOKUP($A9,'ABB ExDa'!$A$2:$N$184, 0,FALSE), IFERROR(VLOOKUP($A9,'Vocus SIT ExDa'!$B$2:$J$173, 0,FALSE), IFERROR(VLOOKUP($A9,'Telstra ExDa'!$B$2:$K$310, 0,FALSE), IFERROR(VLOOKUP($A9,'Vocus RVC ExDa'!$C$2:$R$155, 0,FALSE), IFERROR(VLOOKUP($A9,'Fusion ExDa'!$B$2:$D$16, 0,FALSE), IFERROR(VLOOKUP($A9,'Exetel ExDa'!$C$2:$N$14, 8,FALSE), IFERROR(VLOOKUP($A9,'Infinet ExDa'!$B$2:$E$14, 0,FALSE), "Not Found")))))))) -> Not Found | J9: =IFERROR(VLOOKUP($A9,'AAPT ExDa'!$B$2:$U$99, 7,FALSE), IFERROR(VLOOKUP($A9,'ABB ExDa'!$A$2:$N$184, 2,FALSE), IFERROR(VLOOKUP($A9,'Vocus SIT ExDa'!$B$2:$J$173, 0,FALSE), IFERROR(VLOOKUP($A9,'Telstra ExDa'!$B$2:$K$310, 7,FALSE), IFERROR(VLOOKUP($A9,'Vocus RVC ExDa'!$C$2:$R$155, 2,FALSE), IFERROR(VLOOKUP($A9,'Fusion ExDa'!$B$2:$D$16, 3,FALSE), IFERROR(VLOOKUP($A9,'Exetel ExDa'!$C$2:$N$14, 0,FALSE), IFERROR(VLOOKUP($A9,'Infinet ExDa'!$B$2:$E$14, 0,FALSE), "Not Found")))))))) -> 0 | K9: =IFERROR(VLOOKUP($A9,'AAPT ExDa'!$B$2:$U$99, 12,FALSE), IFERROR(VLOOKUP($A9,'ABB ExDa'!$A$2:$N$184, 0,FALSE), IFERROR(VLOOKUP($A9,'Vocus SIT ExDa'!$B$2:$J$173, 0,FALSE), IFERROR(VLOOKUP($A9,'Telstra ExDa'!$B$2:$K$310, 0,FALSE), IFERROR(VLOOKUP($A9,'Vocus RVC ExDa'!$C$2:$R$155, 0,FALSE), IFERROR(VLOOKUP($A9,'Fusion ExDa'!$B$2:$D$16, 0,FALSE), IFERROR(VLOOKUP($A9,'Exetel ExDa'!$C$2:$N$14, 12,FALSE), IFERROR(VLOOKUP($A9,'Infinet ExDa'!$B$2:$E$14, 0,FALSE), "Not Found")))))))) -> 36 Months | L9: =IFERROR(VLOOKUP($A9,'AAPT ExDa'!$B$2:$U$99, 11,FALSE), IFERROR(VLOOKUP($A9,'ABB ExDa'!$A$2:$N$184, 9,FALSE), IFERROR(VLOOKUP($A9,'Vocus SIT ExDa'!$B$2:$J$173, 8,FALSE), IFERROR(VLOOKUP($A9,'Telstra ExDa'!$B$2:$K$310, 0,FALSE), IFERROR(VLOOKUP($A9,'Vocus RVC ExDa'!$C$2:$R$155, 0,FALSE), IFERROR(VLOOKUP($A9,'Fusion ExDa'!$B$2:$D$16, 0,FALSE), IFERROR(VLOOKUP($A9,'Exetel ExDa'!$C$2:$N$14, 9,FALSE), IFERROR(VLOOKUP($A9,'Infinet ExDa'!$B$2:$E$14, 0,FALSE), "Not Found")))))))) -> 15/04/2022 | M9: =IFERROR(VLOOKUP($A9,'AAPT ExDa'!$B$2:$U$99, 0,FALSE), IFERROR(VLOOKUP($A9,'ABB ExDa'!$A$2:$N$184, 0,FALSE), IFERROR(VLOOKUP($A9,'Vocus SIT ExDa'!$B$2:$J$173, 0,FALSE), IFERROR(VLOOKUP($A9,'Telstra ExDa'!$B$2:$K$310, 0,FALSE), IFERROR(VLOOKUP($A9,'Vocus RVC ExDa'!$C$2:$R$155, 0,FALSE), IFERROR(VLOOKUP($A9,'Fusion ExDa'!$B$2:$D$16, 0,FALSE), IFERROR(VLOOKUP($A9,'Exetel ExDa'!$C$2:$N$14, 11,FALSE), IFERROR(VLOOKUP($A9,'Infinet ExDa'!$B$2:$E$14, 0,FALSE), "Not Found")))))))) -> Not Found | N9: =IFERROR(VLOOKUP($A9,'AAPT ExDa'!$B$2:$U$99, 0,FALSE), IFERROR(VLOOKUP($A9,'ABB ExDa'!$A$2:$N$184, 13,FALSE), IFERROR(VLOOKUP($A9,'Vocus SIT ExDa'!$B$2:$J$173, 0,FALSE), IFERROR(VLOOKUP($A9,'Telstra ExDa'!$B$2:$K$310, 0,FALSE), IFERROR(VLOOKUP($A9,'Vocus RVC ExDa'!$C$2:$R$155, 0,FALSE), IFERROR(VLOOKUP($A9,'Fusion ExDa'!$B$2:$D$16, 0,FALSE), IFERROR(VLOOKUP($A9,'Exetel ExDa'!$C$2:$N$14, 0,FALSE), IFERROR(VLOOKUP($A9,'Infinet ExDa'!$B$2:$E$14, 0,FALSE), "Not Found")))))))) -> Not Found
